Workbook

Sheet Sheet1
A1: STT | B1: Công việc | C1: Cách xử lý | E1: Đánh giá | G1: Hiệu suất cải thiện
C2: Trước khi có tool | D2: Sau khi có tool | E2: Trước khi có tool | F2: Sau khi có tool
A3: 1 | B3: Nhập dữ liệu đường dây | C3: (1) Sử dụng file excel về thông số mẫu của các đường dây. (2) Chọn dây phù hợp (3) Nhập chiều dài đường dây (4) Copy thông số dây và paste vào phần mềm PSS/E (5) Nhập number bus cho đường dây (6) Kết thúc việc nhập liệu đường dây | D3: (1) Nhập number bus, chiều dài dây, số lượng đường dây (2) Chọn thông số dây | E3: (1) Không lưu được thông tin loại đường dây (2) Sử dụng thêm file excel để xử lý dữ liệu trước khi nhập PSS/E (3) Cần cẩn trọng khi nhập liệu, dễ bị sai sót | F3: (1) Lưu được thông tin loại đường dây (2) Nhập dữ liệu ngay trên tool, tool tự động cập nhập vào PSS/E (3) Nhập liệu đơn giản hơn, tránh được sai sót. (4) Rút ngắn được 30% thời gian nhập liệu | G3: 0.3
A4: 2 | B4: Tính toán lưới điện ở chế độ N0 và N-1 (Contingency) | C4: (1) Mở 1 file .sav (2) Mở chức năng tính toán contingency (3) Tạo các .sub .mon .con để thiết lập các tính toán cho contingency. (4) Thực hiện tính toán, kết quả xuất ra dạng file .acc (5) Mở file .acc sau đó copy đưa vào phần mềm excel để dịch sang tiếng Việt và đưa đưa vào báo cáo. | D4: (1) Nhập đường dẫn của tệp chứa các file .sav cần tính (2) Sử dụng chức năng tính toán Auto Contingency (3) Xuất ra kết quả của tất cả các file .sav ra file .acc (4) Mở các file .acc sau đó copy đưa vào phần mềm excel để dịch sang tiếng Việt và đưa đưa vào báo cáo. | E4: (1) Mỗi lần chỉ xử lý được 1 file .sav (2) Xử lý lặp đi lặp lại các bước tính toán cho nhiều file .sav khác nhau (3) Dễ sai sót trong thao tác tính toán. (4) Mất nhiều thời gian để tính toán | F4: (1) Mỗi lần có thể xử lý được nhiều file .sav (2) Không lặp lại các bước tính toán (3) Tránh được sai sót trong thao tác tính toán (4) Tiết kiệm được nhiều thời gian tính toán | G4: 0.4
A5: 3 | B5: Tính toán ổn định tĩnh | C5: (1) Mở 1 file .sav (2) Mở chức năng tính toán ổn định tĩnh (3) Tạo các .sub .mon .con để thiết lập các tính toán cho contingency. (3) Cài đặt các thông số để tính toán (4) Thực hiện tính toán, kết quả xuất ra dạng file .pv (5) Mở file .pv, tổng hợp kết quả tính toán và các đồ thị PV | D5: (1) Nhập đường dẫn của tệp chứa các file .sav cần tính (2) Sử dụng chức năng tính toán ổn định tĩnh (3) Xuất ra kết quả của tất cả các file .sav ra file .pv (4) Mở file .pv, tổng hợp kết quả tính toán và các đồ thị PV | E5: (1) Mỗi lần chỉ xử lý được 1 file .sav (2) Xử lý lặp đi lặp lại các bước tính toán cho nhiều file .sav khác nhau (3) Dễ sai sót trong thao tác tính toán. (4) Mất nhiều thời gian để tính toán | F5: (1) Mỗi lần có thể xử lý được nhiều file .sav (2) Không lặp lại các bước tính toán (3) Tránh được sai sót trong thao tác tính toán (4) Tiết kiệm được nhiều thời gian tính toán | G5: 0.2
A6: 4 | B6: Tính toán ngắn mạch tại thanh cái | C6: (1) Sử dụng file marco để tính ngắn mạch thanh cái để nhập các thanh cái cần tính ngắn mạch. (2) Mở 1 file .sav bằng phần mềm PSS/E (3) Hoàn thành tính toán ngắn mạch cho 1 file .sav (4) Tiếp tục thực hiện thao tác từ (1) đến (3) để tính ngắn mạch có các file .sav khác (5) Copy kết quả tính toán ra file word để tổng hợp. | D6: (1) Mở nhiều file .sav bằng Tool (2) Sử dụng tính năng tính toán ngắn mạch, chọn thanh cái cần tính ngắn mạch / Sử dụng file marco để tính ngắn mạch thanh cái để nhập các thanh cái cần tính ngắn mạch (3) Xuất ra kết quả của tất cả các file .sav cần tính toán ngắn mạch tại thanh cái (4) Tự tổng hợp và xuất ra file word/txt | E6: (1) Chỉ tính được 1 kết quả cho 1 lần tính, lặp lại nhiều lần thao thác tính toán (2) Mất nhiều thời gian xử lý | F6: (1) Tính được nhiều kết quả cho 1 lần tính (2) Rút ngắn được 40% thời gian tính toán | G6: 0.4
A7: 5 | B7: Tính toán kháng bù | C7: (1) Chia thủ công đoạn đường dây làm nhiều đoạn (2) Chọn dung lượng kháng bù và đấu kháng bù vào các thanh cái TBA (theo các nấc bù ví đụ như 50-60-70-80%..) (3) Chạy trào lưu công suất (4) Phần mềm tính ra điện áp dọc tuyến đường dây | D7: (1) Chọn đường dây trong Tools (2)Khai báo trong tools chia đoạn đường dây ra các phần bằng nhau (10%,15%...) (3) Chọn các nấc kháng bù trong tools | E7: (1) Thủ công trong việc tách đường dây ra làm nhiều đoạn. (2) Thủ công trong việc tăng dung lượng kháng bù đến khi điện áp đạt yêu cầu. (3) Thời gian tính toán kiểm tra điện áp lâu | F7: (1) Giảm 2 bước thủ công trong việc chia đường dây và tăng dung lượng kháng bù (2) Rút ngắn được 50% thời gian tính toán | G7: 0.5
A8: 6 | B8: Tính toán ngắn mạch phân bố | C8: (1) Chia thủ công đoạn đường dây làm nhiều đoạn (2) Tính toán ngắn mạch phân bố trên các đoạn đường dây | D8: (1) Tools tự động chia đường dây. Tính toán ngắn mạch phân bố trên cung đoạn đường dây (2) Xuất kết quả tóm tắt và chi tiết ra file txt kèm theo tóm tắt tổng hợp kết quả | E8: (1) Thủ công trong việc tách đường dây ra làm nhiều đoạn. (2) Thủ công trong việc tính toán ngắn mạch trên từng phân đoạn | F8: (1) Giảm 2 bước thủ công trong việc chia đường dây và tính toán ngắn mạch trên các cung đoạn đường dây (2) Rút ngắn được 20% thời gian tính toán | G8: 0.2
A9: 7 | B9: Tính toán ổn định động | C9: (1) Mở 1 file .sav, 1 file .dyr (2) Kiểm tra file .dyr để đủ điều kiện tính toán. Nếu kiểm tra đạt thì tiếp tục tính toán, không đạt thì hiệu chỉnh file .dyr đến khi kiểm tra đạt (3) Thiết lập các cài đặt để tính toán bằng file .idv hoặc thao tác trên phần mềm. (4) Tiến hành chọn thời gian để chạy tính toán ổn định động (5) Cài đặt sự kiện (sự cố tại một/một số phần tử HTĐ) để tính toán. (6) Kết quả được xuất ra dưới dạng file .out (7) Mở file .out, xử lý các đồ thị (đặt tên, canh tọa độ) (8) Đưa các đồ thị vào báo cáo (*) Để cài đặt 1 sự kiện khác cần lặp lại các bước trên. | D9: (1) Mở 1 file .sav, 1 file .dyr hoặc nhiều file .sav (2) Chọn các giá trị cần quan sát trên đồ thị (điện áp, góc máy phát,...) (3) Kiểm tra file .dyr để đủ điều kiện tính toán. Nếu kiểm tra đạt thì tiếp tục tính toán, không đạt thì hiệu chỉnh file .dyr đến khi kiểm tra đạt (4)Thiết lập các sự kiện trong file .idv (5) Chạy tính toán ổn định động. Tự động xuất ra các kết quả tính cho file .out với nhiều sự kiện khác nhau. | E9: (1) Mỗi lần chỉ xử lý được 1 sự kiện (2) Xử lý lặp đi lặp lại các bước tính toán cho mỗi sự kiện khác nhau (3) Dễ sai sót trong thao tác tính toán. (4) Mất nhiều thời gian để tính toán | F9: (1) Mỗi lần có thể xử lý được sự kiện (2) Không lặp lại các bước tính toán (3) Tránh được sai sót trong thao tác tính toán (4) Tiết kiệm được nhiều thời gian tính toán | G9: 0.4
A10: 8 | B10: Chỉnh tên các chế độ trong file ZWCad | C10: (1) Sửa tên từng bản vẽ TLCS trong tính toán bằng ZWCad | D10: (1) Tự động đặt tên các các bản vẽ TLCS bằng ZWCad với tiếng Anh và tiếng Việt | E10: (1) Nhập thủ công (2) Tốn nhiều thời gian (3) Dễ sai sót | F10: (1) Tự động nhập (2) Tiết kiệm nhiều thời gian (4) Tránh được sai sót trong quá trình nhập liệu | G10: 0.6
A11: 9 | B11: Huy động nguồn | C11: (1) Thực hiện huy động nguồn bằng file excel (2) Sao chép công suất huy động được bằng file excel vào PSS/E (3) Thực hiện tính toán trào lưu công suất | D11: (1) Thực hiện huy động nguồn theo tỷ lệ huy động từng loại nguồn, từng miền bằng công cụ. (2) Tự động tính toán trào lưu công suất (3) Hiển thị tỷ lệ huy động của mỗi nguồn để quan sát | E11: (1) Dễ sai sót (2) Khó kiểm soát do có cột hiện thị tỷ lệ huy động của mỗi nguồn | F11: (1) Tránh được sai sót (2) Dễ kiểm soát do có cột hiện thị tỷ lệ huy động của mỗi nguồn | G11: 0.2
A12: 10 | B12: Hiệu chỉnh đồng thời nhiều file | C12: (1) Hiệu chỉnh trên phần mềm PSS/E các nội dung cần cập nhật trong dữ liệu tính toán (2) Lưu lại các thao tác hiệu chỉnh dưới dạng file .py (3) Mở lần lượt từng file dữ liệu tính toán (.sav) chạy lại các file lưu trên (.py) | D12: Cách 1: (1) Hiệu chỉnh trên phần mềm PSS/E các nội dung cần cập nhật trong dữ liệu tính toán (2) Lưu lại các thao tác hiệu chỉnh dưới dạng file .py (3) Nhập đường dẫn của tệp chưa các file .sav cần tính Cách 2: (1) Mở tất cả các file .sav hiệu chỉnh đồng thời. (2) Chỉnh sửa trên một file .sav. Công cụ tự động cập nhật các file .sav còn lại | E12: (1) Mỗi lần chỉ xử lý được 1 file .sav (2) Xử lý lặp đi lặp lại các bước tính toán cho nhiều file .sav khác nhau (3) Dễ sai sót trong thao tác tính toán. (4) Mất nhiều thời gian để tính toán | F12: (1) Mỗi lần có thể xử lý được nhiều file .sav (2) Không lặp lại các bước tính toán (3) Tránh được sai sót trong thao tác tính toán (4) Tiết kiệm được nhiều thời gian tính toán | G12: 0.5
A13: 11 | B13: Tính toán truyền tải liên miền | C13: (1) Mở 1 file .sav (2) Thực hiện cài đặt tính toán bằng chức năng tính toán của ổn định tĩnh: file .sub, .mon, .con (3) Lựa chọn vùng để tính toán công suất truyền tải liên miền (Chỉ chọn được 1 vùng phát và 1 vùng nhận cho truyền tải liên miền) (4) Đưa ra kết quả tính toán | D13: (1) Sử dụng tính năng tính toán truyền tải liên miền (tính toán được nhiều trường hợp truyền tải liên miền) (2) Đưa ra kết quả tính toán | E13: (1) Mỗi lần chỉ tính được 1 trường hợp truyền tải liên miền (2) Xử lý lặp đi lặp lại các bước tính toán cho các trường hợp truyền tải liên miền khác nhau. (3) Dễ sai sót trong thao tác tính toán. (4) Mất nhiều thời gian để tính toán | F13: (1) Mỗi lần tính được nhiều trường hợp truyền tải liên miền cho 1 file .sav (2) Thao tác đơn giản (3) Tiết kiệm được nhiều thời gian tính toán | G13: 0.3

Sheet Sheet2
A1: STT | B1: Tên công việc | C1: Chi tiết công việc | D1: Tính chất công việc | F1: Loại dự án | AC1: Loại dự án | AD1: Tần suất (%) | AE1: Số lần thực hiện TB trong 1 dự án | AF1: % Thời gian thực hiện TB trong 1 dự án | AG1: Tổng điểm khối lượng công việc | AH1: Phần trăm trên tổng khối lượng công việc | AI1: % Khối lượng giảm được sau khi có Tools | AJ1: Tổng điểm khối lượng công việc cho 1 tác vụ = (Tần suất x số lần thực hiện trung bình x % thời gian thực hiện trong 1 dự án) | AL1: Số dự án trong năm 2020 | AM1: 127 | AN1: Số giờ trung bình để thực hiện tổng khối lượng công việc trong năm 2020(giờ) | AO1: =AM1*120 -> 15240
A2: STT | B2: Tên công việc | C2: Chi tiết công việc | E2: Nguồn TĐ | H2: Sau khi có tool | I2: Nguồn NĐ | L2: Sau khi có tool | M2: Nguồn NLTT | P2: Sau khi có tool | Q2: Lưới 500kV | T2: Sau khi có tool | U2: Lưới 220kV | X2: Sau khi có tool | Y2: Lưới 110kV | AB2: Sau khi có tool
A3: 1 | B3: Xây dựng dữ liệu | C3: (1) Tạo bus mới (bus num, bus name) | D3: Mang tính tư duy | E3: 0.25 | F3: 0.1 | G3: =F3*$E$3 -> 0.025 | I3: 0.2 | J3: Có | K3: =J3*I3 -> #VALUE! | M3: 0.2 | N3: Có | O3: =N3*M3 -> #VALUE! | Q3: 0.2 | R3: Có | S3: =R3*Q3 -> #VALUE! | U3: 0.3 | V3: Có | W3: =V3*U3 -> #VALUE! | Y3: 0.3 | Z3: Có | AA3: =Z3*Y3 -> #VALUE! | AC3: Nguồn/Lưới | AD3: 1 | AE3: 300 | AF3: 10 | AG3: =AD3*AE3*AF3 -> 3000 | AH3: =AG3/SUM($AG$3:$AG$44) -> 0.25698133 | AN3: Phần trăm tổng khối lượng giảm được = Trung bình của % khối lượng giảm được của từng tác vụ (Trung bình cột K)
C4: (2) Xác định loại dây, chiều dài dây dẫn, quy mô MBA 2 cuộn dây, 3 cuộn dây, nguồn | D4: Mang tính tư duy | F4: 0.3 | G4: =F4*$E$3 -> 0.075 | J4: Có | K4: =J4*I3 -> #VALUE! | N4: Có | O4: =N4*M3 -> #VALUE! | R4: Có | S4: =R4*Q3 -> #VALUE! | V4: Có | W4: =V4*U3 -> #VALUE! | Z4: Có | AA4: =Z4*Y3 -> #VALUE! | AC4: Nguồn/Lưới | AD4: 1 | AE4: 300 | AF4: 10 | AG4: =AD4*AE4*AF4 -> 3000 | AH4: =AG4/SUM($AG$3:$AG$44) -> 0.25698133 | AJ4: Tần suất xuất hiện: số lần xuất hiện trong 1 dự án/ tổng số dự án | AN4: Số giờ tiết kiệm được khi sử dụng Tools (giờ) | AO4: =AO1*(AO3) -> 0
C5: (3) Nhập chiều dài dây vào file excel thông số đường dây ( hoặc nhập quy mô MBA vào file excel tính thông số MBA) copy phần thông số tương ứng vào PSSE, nhập From bus/To bus | D5: Mang tính lặp lại | F5: 0.4 | G5: =F5*$E$3 -> 0.1 | H5: =G5*AI5 -> 0.07 | J5: 0.1 | K5: =J5*I3 -> 0.02 | L5: =K5*AI5 -> 0.014 | N5: 0.5 | O5: =N5*M3 -> 0.1 | P5: =O5*AI5 -> 0.07 | R5: 0.2 | S5: =R5*Q3 -> 0.04 | T5: =S5*AI5 -> 0.028 | V5: 0.9 | W5: =V5*U3 -> 0.27 | X5: =W5*AI5 -> 0.189 | Z5: 1 | AA5: =Z5*Y3 -> 0.3 | AB5: =AA5*AI5 -> 0.21 | AC5: Nguồn/Lưới | AD5: 1 | AE5: 300 | AF5: 15 | AG5: =AD5*AE5*AF5 -> 4500 | AH5: =AG5/SUM($AG$3:$AG$44) -> 0.38547199 | AI5: 0.7 | AJ5: Thời gian TB: thời gian thực hiện trung bình trong một dự án
C6: (4) Phân vùng phụ tải, scale lại nguồn, tải theo đúng quy mô. | D6: Mang tính tư duy | F6: 0.2 | G6: =F6*$E$3 -> 0.05 | J6: Có | K6: =J6*I3 -> #VALUE! | N6: Có | O6: =N6*M3 -> #VALUE! | R6: Có | S6: =R6*Q3 -> #VALUE! | V6: Có | W6: =V6*U3 -> #VALUE! | Z6: Có | AA6: =Z6*Y3 -> #VALUE! | AC6: Nguồn/Lưới | AD6: 1 | AE6: 3 | AF6: 5 | AG6: =AD6*AE6*AF6 -> 15 | AH6: =AG6/SUM($AG$3:$AG$44) -> 0.0012849066
A7: 2 | B7: Phân vùng phụ tải | C7: (1) Tổng hợp thông tin phụ tải của tỉnh(quốc gia) theo QĐPD QH tỉnh (Quy Hoạch Điện Quốc Gia) của năm tương ứng. | D7: Mang tính tư duy | E7: 0.04 | F7: 0.1 | G7: =F7*$E$7 -> 0.004 | J7: Có | K7: =J7*I7 -> #VALUE! | N7: Có | O7: =N7*M7 -> #VALUE! | R7: Có | S7: =R7*Q7 -> #VALUE! | V7: Có | W7: =V7*U7 -> #VALUE! | Z7: Có | AA7: =Z7*Y7 -> #VALUE! | AC7: Nguồn/Lưới | AD7: 1 | AE7: 6 | AF7: 2 | AG7: =AD7*AE7*AF7 -> 12 | AH7: =AG7/SUM($AG$3:$AG$44) -> 0.0010279253
C8: (2) Tổng hợp thông tin phân vùng phụ tải của từng phân vùng và quy mô tương ứng | D8: Mang tính tư duy | F8: 0.1 | G8: =F8*$E$7 -> 0.004 | J8: Có | K8: =J8*I7 -> #VALUE! | N8: Có | O8: =N8*M7 -> #VALUE! | R8: Có | S8: =R8*Q7 -> #VALUE! | V8: Có | W8: =V8*U7 -> #VALUE! | Z8: Có | AA8: =Z8*Y7 -> #VALUE! | AC8: Nguồn/Lưới | AD8: 1 | AE8: 6 | AF8: 2 | AG8: =AD8*AE8*AF8 -> 12 | AH8: =AG8/SUM($AG$3:$AG$44) -> 0.0010279253 | AN8: =120/8 -> 15
C9: (3) Phân lại phụ tải theo quy mô tổng và tỉ lệ của từng phân vùng | D9: Mang tính tư duy | F9: 0.8 | G9: =F9*$E$7 -> 0.032 | J9: Có | K9: =J9*I7 -> #VALUE! | N9: Có | O9: =N9*M7 -> #VALUE! | R9: Có | S9: =R9*Q7 -> #VALUE! | V9: Có | W9: =V9*U7 -> #VALUE! | Z9: Có | AA9: =Z9*Y7 -> #VALUE! | AC9: Nguồn/Lưới | AD9: 1 | AE9: 6 | AF9: 6 | AG9: =AD9*AE9*AF9 -> 36 | AH9: =AG9/SUM($AG$3:$AG$44) -> 0.0030837759
A10: 3 | B10: Tính toán lưới điện ở chế độ N0 và N-1 (Contingency) | C10: (1) Tạo các .sub .mon .con để thiết lập các tính toán cho contingency. | D10: Mang tính lặp lại | E10: 0.15 | F10: 0.1 | G10: =F10*$E$10 -> 0.015 | H10: =G10*AI10 -> 0.012 | I10: 0.1 | J10: 0.1 | K10: =J10*I10 -> 0.01 | L10: =K10*AI10 -> 0.008 | M10: 0.1 | N10: 0.1 | O10: =N10*M10 -> 0.01 | P10: =O10*AI10 -> 0.008 | Q10: 0.1 | R10: 0.1 | S10: =R10*Q10 -> 0.01 | T10: =S10*AI10 -> 0.008 | U10: 0.1 | V10: 0.1 | W10: =V10*U10 -> 0.01 | X10: =W10*AI10 -> 0.008 | Y10: 0.1 | Z10: 0.1 | AA10: =Z10*Y10 -> 0.01 | AB10: =AA10*AI10 -> 0.008 | AC10: Nguồn/Lưới | AD10: 1 | AE10: 3 | AF10: 1 | AG10: =AD10*AE10*AF10 -> 3 | AH10: =AG10/SUM($AG$3:$AG$44) -> 0.00025698133 | AI10: 0.8
C11: (2) Mở chức năng tính toán contingency, nhập đường dẫn các file sub, mon, con đã tạo và nhập tên file kết quả. | D11: Mang tính lặp lại | F11: 0.1 | G11: =F11*$E$10 -> 0.015 | H11: =G11*AI11 -> 0.012 | J11: 0.1 | K11: =J11*I10 -> 0.01 | L11: =K11*AI11 -> 0.008 | N11: 0.1 | O11: =N11*M10 -> 0.01 | P11: =O11*AI11 -> 0.008 | R11: 0.1 | S11: =R11*Q10 -> 0.01 | T11: =S11*AI11 -> 0.008 | V11: 0.1 | W11: =V11*U10 -> 0.01 | X11: =W11*AI11 -> 0.008 | Z11: 0.1 | AA11: =Z11*Y10 -> 0.01 | AB11: =AA11*AI11 -> 0.008 | AC11: Nguồn/Lưới | AD11: 1 | AE11: 6 | AF11: 2 | AG11: =AD11*AE11*AF11 -> 12 | AH11: =AG11/SUM($AG$3:$AG$44) -> 0.0010279253 | AI11: 0.8
C12: (3) Thực hiện tính toán, kết quả xuất ra dạng file .acc | D12: Mang tính lặp lại | F12: 0.2 | G12: =F12*$E$10 -> 0.03 | H12: =G12*AI12 -> 0.024 | J12: 0.1 | K12: =J12*I10 -> 0.01 | L12: =K12*AI12 -> 0.008 | N12: 0.2 | O12: =N12*M10 -> 0.02 | P12: =O12*AI12 -> 0.016 | R12: 0.2 | S12: =R12*Q10 -> 0.02 | T12: =S12*AI12 -> 0.016 | V12: 0.2 | W12: =V12*U10 -> 0.02 | X12: =W12*AI12 -> 0.016 | Z12: 0.2 | AA12: =Z12*Y10 -> 0.02 | AB12: =AA12*AI12 -> 0.016 | AC12: Nguồn/Lưới | AD12: 1 | AE12: 6 | AF12: 5 | AG12: =AD12*AE12*AF12 -> 30 | AH12: =AG12/SUM($AG$3:$AG$44) -> 0.0025698133 | AI12: 0.8
C13: (4) Mở file .acc sau đó copy đưa vào phần mềm excel để dịch sang tiếng Việt và đưa vào báo cáo. | D13: Mang tính lặp lại | F13: 0.2 | G13: =F13*$E$10 -> 0.03 | H13: =G13*AI13 -> 0.024 | J13: 0.1 | K13: =J13*I10 -> 0.01 | L13: =K13*AI13 -> 0.008 | N13: 0.2 | O13: =N13*M10 -> 0.02 | P13: =O13*AI13 -> 0.016 | R13: 0.2 | S13: =R13*Q10 -> 0.02 | T13: =S13*AI13 -> 0.016 | V13: 0.2 | W13: =V13*U10 -> 0.02 | X13: =W13*AI13 -> 0.016 | Z13: 0.2 | AA13: =Z13*Y10 -> 0.02 | AB13: =AA13*AI13 -> 0.016 | AC13: Nguồn/Lưới | AD13: 1 | AE13: 6 | AF13: 4 | AG13: =AD13*AE13*AF13 -> 24 | AH13: =AG13/SUM($AG$3:$AG$44) -> 0.0020558506 | AI13: 0.8
C14: (5) Tổng hợp kết quả, phân tích và đánh giá | D14: Mang tính tư duy | F14: 0.4 | G14: =F14*$E$10 -> 0.06 | J14: Có | K14: =J14*$I$10 -> #VALUE! | N14: Có | O14: =N14*$I$10 -> #VALUE! | R14: Có | S14: =R14*$I$10 -> #VALUE! | V14: Có | W14: =V14*$I$10 -> #VALUE! | Z14: Có | AA14: =Z14*$I$10 -> #VALUE! | AC14: Nguồn/Lưới | AD14: 1 | AE14: 6 | AF14: 8 | AG14: =AD14*AE14*AF14 -> 48 | AH14: =AG14/SUM($AG$3:$AG$44) -> 0.0041117012
A15: 4 | B15: Tính toán ổn định tĩnh | C15: (1) Tạo các file .sub .mon .con để thiết lập các tính toán cho ổn định tĩnh. | D15: Mang tính tư duy | E15: 0.15 | F15: 0.1 | G15: =F15*$E$15 -> 0.015 | I15: 0.1 | J15: Có | K15: =J15*I15 -> #VALUE! | M15: 0 | N15: Có | O15: =N15*M15 -> #VALUE! | Q15: 0.05 | S15: =R15*Q15 -> 0 | U15: 0 | W15: =V15*U15 -> 0 | AA15: =Z15*Y15 -> 0 | AC15: Nguồn | AD15: 1 | AE15: 3 | AF15: 1 | AG15: =AD15*AE15*AF15 -> 3 | AH15: =AG15/SUM($AG$3:$AG$44) -> 0.00025698133
C16: (2) Mở chức năng tính toán ổn định tĩnh, nhập đường dẫn các file sub, mon, con đã tạo và nhập tên file kết quả, chọn Sink/Source. | D16: Mang tính lặp lại | F16: 0.1 | G16: =F16*$E$15 -> 0.015 | H16: =G16*AI16 -> 0.012 | J16: 0.05 | K16: =J16*I15 -> 0.005 | L16: =K16*AI16 -> 0.004 | O16: =N16*M15 -> 0 | P16: =O16*AI16 -> 0 | R16: 0.1 | S16: =R16*Q15 -> 0.005 | T16: =S16*AI16 -> 0.004 | W16: =V16*U15 -> 0 | X16: =W16*AI16 -> 0 | AA16: =Z16*Y15 -> 0 | AB16: =AA16*AI16 -> 0 | AC16: Nguồn | AD16: 1 | AE16: 6 | AF16: 4 | AG16: =AD16*AE16*AF16 -> 24 | AH16: =AG16/SUM($AG$3:$AG$44) -> 0.0020558506 | AI16: 0.8
C17: (3) Thực hiện tính toán, kết quả xuất ra dạng file .pv | D17: Mang tính lặp lại | F17: 0.3 | G17: =F17*$E$15 -> 0.045 | H17: =G17*AI17 -> 0.036 | J17: 0.05 | K17: =J17*I15 -> 0.005 | L17: =K17*AI17 -> 0.004 | O17: =N17*M15 -> 0 | P17: =O17*AI17 -> 0 | R17: 0.1 | S17: =R17*Q15 -> 0.005 | T17: =S17*AI17 -> 0.004 | W17: =V17*U15 -> 0 | X17: =W17*AI17 -> 0 | AA17: =Z17*Y15 -> 0 | AB17: =AA17*AI17 -> 0 | AC17: Nguồn | AD17: 1 | AE17: 6 | AF17: 5 | AG17: =AD17*AE17*AF17 -> 30 | AH17: =AG17/SUM($AG$3:$AG$44) -> 0.0025698133 | AI17: 0.8
C18: (4) Mở file .pv, tổng hợp kết quả tính toán và các đồ thị PV, phân tích, đánh gía kết quả. | D18: Mang tính tư duy | F18: 0.5 | G18: =F18*$E$15 -> 0.075 | J18: Có | K18: =J18*I15 -> #VALUE! | N18: Có | O18: =N18*M15 -> #VALUE! | S18: =R18*Q15 -> 0 | W18: =V18*U15 -> 0 | AA18: =Z18*Y15 -> 0 | AC18: Nguồn/Lưới | AD18: 1 | AE18: 6 | AF18: 10 | AG18: =AD18*AE18*AF18 -> 60 | AH18: =AG18/SUM($AG$3:$AG$44) -> 0.0051396265
A19: 5 | B19: Tính toán ngắn mạch tại thanh cái | C19: (1) Tạo file marco để tính ngắn mạch thanh cái để nhập các thanh cái cần tính ngắn mạch. | D19: Mang tính tư duy | G19: =F19*$E$19 -> 0 | I19: 0.1 | K19: =J19*I19 -> 0 | M19: 0.1 | O19: =N19*M19 -> 0 | Q19: 0.05 | R19: Có | S19: =R19*Q19 -> #VALUE! | U19: 0.1 | V19: Có | W19: =V19*U19 -> #VALUE! | Y19: 0.1 | Z19: Có | AA19: =Z19*Y19 -> #VALUE! | AC19: Nguồn/Lưới | AD19: 1 | AE19: 3 | AF19: 1 | AG19: =AD19*AE19*AF19 -> 3 | AH19: =AG19/SUM($AG$3:$AG$44) -> 0.00025698133
C20: (2) Tính toán ngắn mạch cho file .sav với file macro đã tạo. | D20: Mang tính lặp lại | G20: =F20*$E$19 -> 0 | H20: =G20*AI20 -> 0 | J20: 0.05 | K20: =J20*I19 -> 0.005 | L20: =K20*AI20 -> 0.004 | N20: 0.1 | O20: =N20*M19 -> 0.01 | P20: =O20*AI20 -> 0.008 | R20: 0.1 | S20: =R20*Q19 -> 0.005 | T20: =S20*AI20 -> 0.004 | V20: 0.1 | W20: =V20*U19 -> 0.01 | X20: =W20*AI20 -> 0.008 | Z20: 0.1 | AA20: =Z20*Y19 -> 0.01 | AB20: =AA20*AI20 -> 0.008 | AC20: Nguồn/Lưới | AD20: 1 | AE20: 6 | AF20: 4 | AG20: =AD20*AE20*AF20 -> 24 | AH20: =AG20/SUM($AG$3:$AG$44) -> 0.0020558506 | AI20: 0.8
C21: (3) Copy kết quả tính toán ra file word để tổng hợp, chọn ra các giá trị dòng ngắn mạch tổng tại các bus quan sát. | D21: Mang tính lặp lại | G21: =F21*$E$19 -> 0 | H21: =G21*AI21 -> 0 | J21: 0.05 | K21: =J21*I19 -> 0.005 | L21: =K21*AI21 -> 0.004 | N21: 0.1 | O21: =N21*M19 -> 0.01 | P21: =O21*AI21 -> 0.008 | R21: 0.1 | S21: =R21*Q19 -> 0.005 | T21: =S21*AI21 -> 0.004 | V21: 0.1 | W21: =V21*U19 -> 0.01 | X21: =W21*AI21 -> 0.008 | Z21: 0.1 | AA21: =Z21*Y19 -> 0.01 | AB21: =AA21*AI21 -> 0.008 | AC21: Nguồn/Lưới | AD21: 1 | AE21: 6 | AF21: 5 | AG21: =AD21*AE21*AF21 -> 30 | AH21: =AG21/SUM($AG$3:$AG$44) -> 0.0025698133 | AI21: 0.8
C22: (4) Tổng hợp kết quả, phân tích, đánh giá | D22: Mang tính tư duy | G22: =F22*$E$19 -> 0 | K22: =J22*I19 -> 0 | O22: =N22*M19 -> 0 | R22: Có | S22: =R22*Q19 -> #VALUE! | V22: Có | W22: =V22*U19 -> #VALUE! | Z22: Có | AA22: =Z22*Y19 -> #VALUE! | AC22: Nguồn/Lưới | AD22: 1 | AE22: 6 | AF22: 10 | AG22: =AD22*AE22*AF22 -> 60 | AH22: =AG22/SUM($AG$3:$AG$44) -> 0.0051396265
A23: 6 | B23: Tính toán kháng bù | C23: (1) Tạo file python chia đoạn đường dây làm nhiều đoạn (8 hoặc 16 đoạn). | D23: Mang tính tư duy | G23: =F23*$E$23 -> 0 | K23: =J23*I23 -> 0 | O23: =N23*M23 -> 0 | Q23: 0.05 | R23: Có | S23: =R23*Q23 -> #VALUE! | U23: 0 | V23: Có | W23: =V23*U23 -> #VALUE! | Z23: Có | AA23: =Z23*Y23 -> #VALUE! | AC23: Nguồn/Lưới | AD23: 1 | AE23: 1 | AF23: 5 | AG23: =AD23*AE23*AF23 -> 5 | AH23: =AG23/SUM($AG$3:$AG$44) -> 0.00042830221
C24: (2) Chọn dung lượng kháng bù và đấu kháng bù vào các thanh cái TBA (theo các nấc bù ví dụ như 50-60-70-80%..) | D24: Mang tính lặp lại | G24: =F24*$E$23 -> 0 | H24: =G24*AI24 -> 0 | K24: =J24*I23 -> 0 | L24: =K24*AI24 -> 0 | O24: =N24*M23 -> 0 | P24: =O24*AI24 -> 0 | R24: 0.1 | S24: =R24*Q23 -> 0.005 | T24: =S24*AI24 -> 0.0035 | W24: =V24*U23 -> 0 | X24: =W24*AI24 -> 0 | AA24: =Z24*Y23 -> 0 | AB24: =AA24*AI24 -> 0 | AC24: Nguồn/Lưới | AD24: 1 | AE24: 3 | AF24: 5 | AG24: =AD24*AE24*AF24 -> 15 | AH24: =AG24/SUM($AG$3:$AG$44) -> 0.0012849066 | AI24: 0.7
C25: (3) Tính trào lưu công suất và tổng hợp giá trị điện áp dọc tuyến đường dây | D25: Mang tính lặp lại | G25: =F25*$E$23 -> 0 | H25: =G25*AI25 -> 0 | K25: =J25*I23 -> 0 | L25: =K25*AI25 -> 0 | O25: =N25*M23 -> 0 | P25: =O25*AI25 -> 0 | R25: 0.1 | S25: =R25*Q23 -> 0.005 | T25: =S25*AI25 -> 0.0035 | W25: =V25*U23 -> 0 | X25: =W25*AI25 -> 0 | AA25: =Z25*Y23 -> 0 | AB25: =AA25*AI25 -> 0 | AC25: Nguồn/Lưới | AD25: 1 | AE25: 3 | AF25: 5 | AG25: =AD25*AE25*AF25 -> 15 | AH25: =AG25/SUM($AG$3:$AG$44) -> 0.0012849066 | AI25: 0.7
C26: (4) Tổng hợp kết quả, phân tích, đánh giá. | D26: Mang tính tư duy | G26: =F26*$E$23 -> 0 | K26: =J26*I23 -> 0 | O26: =N26*M23 -> 0 | R26: Có | S26: =R26*Q23 -> #VALUE! | V26: Có | W26: =V26*U23 -> #VALUE! | Z26: Có | AA26: =Z26*Y23 -> #VALUE! | AC26: Đường dây | AD26: 1 | AE26: 3 | AF26: 5 | AG26: =AD26*AE26*AF26 -> 15 | AH26: =AG26/SUM($AG$3:$AG$44) -> 0.0012849066
A27: 7 | B27: Tính toán ngắn mạch phân bố | C27: (1) Chia thủ công đoạn đường dây làm nhiều đoạn | D27: Mang tính tư duy | G27: =F27*$E$27 -> 0 | K27: =J27*I27 -> 0 | O27: =N27*M27 -> 0 | Q27: 0.05 | R27: Có | S27: =R27*Q27 -> #VALUE! | U27: 0.1 | V27: Có | W27: =V27*U27 -> #VALUE! | Y27: 0.1 | Z27: Có | AA27: =Z27*Y27 -> #VALUE! | AC27: Đường dây | AD27: 1 | AE27: 1 | AF27: 5 | AG27: =AD27*AE27*AF27 -> 5 | AH27: =AG27/SUM($AG$3:$AG$44) -> 0.00042830221
C28: (2) Tạo file tính ngắn mạch cho các đoạn đường dây đã chia. | D28: Mang tính lặp lại | G28: =F28*$E$27 -> 0 | H28: =G28*AI28 -> 0 | K28: =J28*I27 -> 0 | L28: =K28*AI28 -> 0 | O28: =N28*M27 -> 0 | P28: =O28*AI28 -> 0 | R28: 0.1 | S28: =R28*Q27 -> 0.005 | T28: =S28*AI28 -> 0.0035 | V28: 0.1 | W28: =V28*U27 -> 0.01 | X28: =W28*AI28 -> 0.007 | Z28: 0.1 | AA28: =Z28*Y27 -> 0.01 | AB28: =AA28*AI28 -> 0.007 | AC28: Đường dây | AD28: 1 | AE28: 3 | AF28: 1 | AG28: =AD28*AE28*AF28 -> 3 | AH28: =AG28/SUM($AG$3:$AG$44) -> 0.00025698133 | AI28: 0.7
C29: (3) Tính toán ngắn mạch phân bố trên các đoạn đường dây. | D29: Mang tính lặp lại | G29: =F29*$E$27 -> 0 | H29: =G29*AI29 -> 0 | K29: =J29*I27 -> 0 | L29: =K29*AI29 -> 0 | O29: =N29*M27 -> 0 | P29: =O29*AI29 -> 0 | R29: 0.1 | S29: =R29*Q27 -> 0.005 | T29: =S29*AI29 -> 0.0035 | V29: 0.1 | W29: =V29*U27 -> 0.01 | X29: =W29*AI29 -> 0.007 | Z29: 0.1 | AA29: =Z29*Y27 -> 0.01 | AB29: =AA29*AI29 -> 0.007 | AC29: Đường dây | AD29: 1 | AE29: 3 | AF29: 4 | AG29: =AD29*AE29*AF29 -> 12 | AH29: =AG29/SUM($AG$3:$AG$44) -> 0.0010279253 | AI29: 0.7
C30: (4) Tổng hợp kết quả tính toán, phân tích, đánh giá. | D30: Mang tính tư duy | G30: =F30*$E$27 -> 0 | K30: =J30*I27 -> 0 | O30: =N30*M27 -> 0 | R30: Có | S30: =R30*Q27 -> #VALUE! | V30: Có | W30: =V30*U27 -> #VALUE! | Z30: Có | AA30: =Z30*Y27 -> #VALUE! | AC30: Đường dây | AD30: 1 | AE30: 3 | AF30: 10 | AG30: =AD30*AE30*AF30 -> 30 | AH30: =AG30/SUM($AG$3:$AG$44) -> 0.0025698133
A31: 8 | B31: Tính toán ổn định động | C31: (1) Tạo file dữ liệu động cho các tổ máy (.dyr) | D31: Mang tính tư duy | E31: 0.15 | F31: 0.2 | G31: =F31*$E$31 -> 0.03 | I31: 0.1 | J31: Có | K31: =J31*I31 -> #VALUE! | M31: 0.1 | N31: Có | O31: =N31*M31 -> #VALUE! | Q31: 0.1 | S31: =R31*Q31 -> 0 | W31: =V31*U31 -> 0 | AA31: =Z31*Y31 -> 0 | AC31: Nguồn | AD31: 1 | AE31: 1 | AF31: 10 | AG31: =AD31*AE31*AF31 -> 10 | AH31: =AG31/SUM($AG$3:$AG$44) -> 0.00085660442
C32: (2) Kiểm tra file .dyr để đủ điều kiện tính toán. Nếu kiểm tra đạt thì tiếp tục tính toán, không đạt thì hiệu chỉnh file .dyr đến khi kiểm tra đạt. | D32: Mang tính lặp lại | F32: 0.1 | G32: =F32*$E$31 -> 0.015 | H32: =G32*AI32 -> 0.0105 | J32: 0.05 | K32: =J32*I31 -> 0.005 | L32: =K32*AI32 -> 0.0035 | N32: 0.1 | O32: =N32*M31 -> 0.01 | P32: =O32*AI32 -> 0.007 | R32: 0.1 | S32: =R32*Q31 -> 0.01 | T32: =S32*AI32 -> 0.007 | W32: =V32*U31 -> 0 | X32: =W32*AI32 -> 0 | AA32: =Z32*Y31 -> 0 | AB32: =AA32*AI32 -> 0 | AC32: Nguồn | AD32: 1 | AE32: 3 | AF32: 3 | AG32: =AD32*AE32*AF32 -> 9 | AH32: =AG32/SUM($AG$3:$AG$44) -> 0.00077094398 | AI32: 0.7
C33: (3) Thiết lập các cài đặt để tính toán bằng file .idv hoặc thao tác trên phần mềm. | D33: Mang tính tư duy | F33: 0.1 | G33: =F33*$E$31 -> 0.015 | J33: Có | K33: =J33*I31 -> #VALUE! | N33: Có | O33: =N33*M31 -> #VALUE! | S33: =R33*Q31 -> 0 | W33: =V33*U31 -> 0 | AA33: =Z33*Y31 -> 0 | AC33: Nguồn | AD33: 1 | AE33: 3 | AF33: 2 | AG33: =AD33*AE33*AF33 -> 6 | AH33: =AG33/SUM($AG$3:$AG$44) -> 0.00051396265 | AI33: 0.7
C34: (4) Cài đặt sự kiện (sự cố tại một/một số phần tử HTĐ) để tính toán. | D34: Mang tính tư duy | F34: 0.2 | G34: =F34*$E$31 -> 0.03 | J34: Có | K34: =J34*I31 -> #VALUE! | N34: Có | O34: =N34*M31 -> #VALUE! | S34: =R34*Q31 -> 0 | W34: =V34*U31 -> 0 | AA34: =Z34*Y31 -> 0 | AC34: Nguồn | AD34: 1 | AE34: 3 | AF34: 5 | AG34: =AD34*AE34*AF34 -> 15 | AH34: =AG34/SUM($AG$3:$AG$44) -> 0.0012849066 | AI34: 0.7
C35: (5) Mở file kết quả (.out), xử lý các đồ thị (đặt tên, canh tọa độ). | D35: Mang tính lặp lại | F35: 0.2 | G35: =F35*$E$31 -> 0.03 | H35: =G35*AI35 -> 0.021 | J35: 0.05 | K35: =J35*I31 -> 0.005 | L35: =K35*AI35 -> 0.0035 | N35: 0.1 | O35: =N35*M31 -> 0.01 | P35: =O35*AI35 -> 0.007 | R35: 0.1 | S35: =R35*Q31 -> 0.01 | T35: =S35*AI35 -> 0.007 | W35: =V35*U31 -> 0 | X35: =W35*AI35 -> 0 | AA35: =Z35*Y31 -> 0 | AB35: =AA35*AI35 -> 0 | AC35: Nguồn | AD35: 1 | AE35: 3 | AF35: 5 | AG35: =AD35*AE35*AF35 -> 15 | AH35: =AG35/SUM($AG$3:$AG$44) -> 0.0012849066 | AI35: 0.7
C36: (6) Đánh giá và lập báo cáo. | D36: Mang tính tư duy | F36: 0.2 | G36: =F36*$E$31 -> 0.03 | J36: Có | K36: =J36*I31 -> #VALUE! | N36: Có | O36: =N36*M31 -> #VALUE! | S36: =R36*Q31 -> 0 | W36: =V36*U31 -> 0 | AA36: =Z36*Y31 -> 0 | AC36: Nguồn | AD36: 1 | AE36: 3 | AF36: 5 | AG36: =AD36*AE36*AF36 -> 15 | AH36: =AG36/SUM($AG$3:$AG$44) -> 0.0012849066 | AI36: 0.7
A37: 9 | B37: Chỉnh tên các chế độ trong file ZWCad | C37: (1) Sửa tên từng bản vẽ TLCS trong tính toán bằng ZWCad theo đúng chế độ phụ tải và mùa cũng như kịch bản tương ứng. | D37: Mang tính lặp lại | E37: 0.01 | F37: 1 | G37: =F37*$E$37 -> 0.01 | H37: =G37*AI37 -> 0.0068 | I37: 0.2 | J37: 1 | K37: =J37*I37 -> 0.2 | L37: =K37*AI37 -> 0.136 | M37: 0.2 | N37: 1 | O37: =N37*M37 -> 0.2 | P37: =O37*AI37 -> 0.136 | Q37: 0.2 | R37: 1 | S37: =R37*Q37 -> 0.2 | T37: =S37*AI37 -> 0.136 | U37: 0.2 | V37: 1 | W37: =V37*U37 -> 0.2 | X37: =W37*AI37 -> 0.136 | Y37: 0.2 | Z37: 1 | AA37: =Z37*Y37 -> 0.2 | AB37: =AA37*AI37 -> 0.136 | AC37: Nguồn/Lưới | AD37: 1 | AE37: 100 | AF37: 5 | AG37: =AD37*AE37*AF37 -> 500 | AH37: =AG37/SUM($AG$3:$AG$44) -> 0.042830221 | AI37: 0.68
A38: 10 | B38: Huy động nguồn | C38: (1) Thực hiện huy động nguồn bằng file excel | D38: Mang tính tư duy | E38: 0.05 | F38: 0.8 | G38: =F38*$E$38 -> 0.04 | I38: 0.1 | J38: Có | K38: =J38*I38 -> #VALUE! | M38: 0.2 | N38: Có | O38: =N38*M38 -> #VALUE! | Q38: 0.1 | R38: Có | S38: =R38*Q38 -> #VALUE! | U38: 0.1 | V38: Có | W38: =V38*U38 -> #VALUE! | Y38: 0.1 | Z38: Có | AA38: =Z38*Y38 -> #VALUE! | AC38: Nguồn/Lưới | AD38: 1 | AE38: 6 | AF38: 8 | AG38: =AD38*AE38*AF38 -> 48 | AH38: =AG38/SUM($AG$3:$AG$44) -> 0.0041117012 | AI38: 0.6
C39: (2) Sao chép công suất huy động được bằng file excel vào PSS/E và tính lại TLCS | D39: Mang tính lặp lại | F39: 0.2 | G39: =F39*$E$38 -> 0.01 | H39: =G39*AI39 -> 0.006 | J39: 0.1 | K39: =J39*I38 -> 0.01 | L39: =K39*AI39 -> 0.006 | N39: 0.01 | O39: =N39*M38 -> 0.002 | P39: =O39*AI39 -> 0.0012 | R39: 1 | S39: =R39*Q38 -> 0.1 | T39: =S39*AI39 -> 0.06 | V39: 0.1 | W39: =V39*U38 -> 0.01 | X39: =W39*AI39 -> 0.006 | Z39: 0.1 | AA39: =Z39*Y38 -> 0.01 | AB39: =AA39*AI39 -> 0.006 | AC39: Nguồn/Lưới | AD39: 1 | AE39: 6 | AF39: 2 | AG39: =AD39*AE39*AF39 -> 12 | AH39: =AG39/SUM($AG$3:$AG$44) -> 0.0010279253 | AI39: 0.6
A40: 11 | B40: Tính toán truyền tải liên miền | C40: (1) Thực hiện cài đặt tính toán bằng chức năng tính toán của ổn định tĩnh: file .sub, .mon, .con | D40: Mang tính tư duy | G40: =F40*$E$40 -> 0 | K40: =J40*I40 -> 0 | O40: =N40*M40 -> 0 | R40: Có | S40: =R40*Q40 -> #VALUE! | V40: Có | W40: =V40*U40 -> #VALUE! | Z40: Có | AA40: =Z40*Y40 -> #VALUE! | AC40: Nguồn/Lưới | AD40: 1 | AE40: 1 | AF40: 1 | AG40: =AD40*AE40*AF40 -> 1 | AH40: =AG40/SUM($AG$3:$AG$44) -> 8.5660442e-05
...

Sheet Trang_tính1
A1: STT | B1: Tên công việc | C1: STT | D1: Tên công việc
A2: 1 | B2: Xây dựng dữ liệu | C2: 7 | D2: Tính toán ngắn mạch phân bố
A3: 2 | B3: Phân vùng phụ tải | C3: 8 | D3: Tính toán ổn định động
A4: 3 | B4: Tính toán lưới điện ở chế độ N0 và N-1 (Contingency) | C4: 9 | D4: Chỉnh tên các chế độ trong file ZWCad
A5: 4 | B5: Tính toán ổn định tĩnh | C5: 10 | D5: Huy động nguồn
A6: 5 | B6: Tính toán ngắn mạch tại thanh cái | C6: 11 | D6: Tính toán truyền tải liên miền
A7: 6 | B7: Tính toán kháng bù | C7: 12 | D7: Lập báo cáo
C8: 13 | D8: Lập phụ lục bản vẽ và tính toán

Sheet Sheet3
A1: STT | B1: Tên công việc | C1: Tính chất công việc | D1: Loại dự án | E1: Tần suất (%) | F1: Số lần thực hiện TB trong 1 dự án | G1: % Thời gian thực hiện TB trong 1 dự án | H1: Tổng điểm khối lượng công việc | I1: Phần trăm trên tổng khối lượng công việc | J1: % Khối lượng giảm được sau khi có Tools | K1: Tổng điểm khối lượng công việc cho 1 tác vụ = (Tần suất x số lần thực hiện trung bình x % thời gian thực hiện trong 1 dự án) | M1: Số dự án trong năm 2020 | N1: 142 | O1: Số giờ trung bình để thực hiện tổng khối lượng công việc trong năm 2020(giờ) | P1: =N1*120 -> 17040
A2: 1 | B2: Xây dựng dữ liệu | C2: Mang tính tư duy | D2: Nguồn/Lưới | E2: 1 | F2: 300 | G2: 10 | H2: =E2*F2*G2 -> 3000 | I2: =H2/SUM($H$2:$H$43) -> 0.25698133 | O2: Phần trăm tổng khối lượng giảm được = Trung bình của % khối lượng giảm được của từng tác vụ (Trung bình cột K)
C3: Mang tính tư duy | D3: Nguồn/Lưới | E3: 1 | F3: 300 | G3: 10 | H3: =E3*F3*G3 -> 3000 | I3: =H3/SUM($H$2:$H$43) -> 0.25698133 | K3: Tần suất xuất hiện: số lần xuất hiện trong 1 dự án/ tổng số dự án | O3: Số giờ tiết kiệm được khi sử dụng Tools (giờ) | P3: =P1*(P2) -> 0
C4: Mang tính lặp lại | D4: Nguồn/Lưới | E4: 1 | F4: 300 | G4: 15 | H4: =E4*F4*G4 -> 4500 | I4: =H4/SUM($H$2:$H$43) -> 0.38547199 | K4: Thời gian TB: thời gian thực hiện trung bình trong một dự án
C5: Mang tính tư duy | D5: Nguồn/Lưới | E5: 1 | F5: 3 | G5: 5 | H5: =E5*F5*G5 -> 15 | I5: =H5/SUM($H$2:$H$43) -> 0.0012849066
A6: 2 | B6: Phân vùng phụ tải | C6: Mang tính tư duy | D6: Nguồn/Lưới | E6: 1 | F6: 6 | G6: 2 | H6: =E6*F6*G6 -> 12 | I6: =H6/SUM($H$2:$H$43) -> 0.0010279253
C7: Mang tính tư duy | D7: Nguồn/Lưới | E7: 1 | F7: 6 | G7: 2 | H7: =E7*F7*G7 -> 12 | I7: =H7/SUM($H$2:$H$43) -> 0.0010279253
C8: Mang tính tư duy | D8: Nguồn/Lưới | E8: 1 | F8: 6 | G8: 6 | H8: =E8*F8*G8 -> 36 | I8: =H8/SUM($H$2:$H$43) -> 0.0030837759
A9: 3 | B9: Tính toán lưới điện ở chế độ N0 và N-1 (Contingency) | C9: Mang tính lặp lại | D9: Nguồn/Lưới | E9: 1 | F9: 3 | G9: 1 | H9: =E9*F9*G9 -> 3 | I9: =H9/SUM($H$2:$H$43) -> 0.00025698133
C10: Mang tính lặp lại | D10: Nguồn/Lưới | E10: 1 | F10: 6 | G10: 2 | H10: =E10*F10*G10 -> 12 | I10: =H10/SUM($H$2:$H$43) -> 0.0010279253
C11: Mang tính lặp lại | D11: Nguồn/Lưới | E11: 1 | F11: 6 | G11: 5 | H11: =E11*F11*G11 -> 30 | I11: =H11/SUM($H$2:$H$43) -> 0.0025698133
C12: Mang tính lặp lại | D12: Nguồn/Lưới | E12: 1 | F12: 6 | G12: 4 | H12: =E12*F12*G12 -> 24 | I12: =H12/SUM($H$2:$H$43) -> 0.0020558506
C13: Mang tính tư duy | D13: Nguồn/Lưới | E13: 1 | F13: 6 | G13: 8 | H13: =E13*F13*G13 -> 48 | I13: =H13/SUM($H$2:$H$43) -> 0.0041117012
A14: 4 | B14: Tính toán ổn định tĩnh | C14: Mang tính tư duy | D14: Nguồn | E14: 1 | F14: 3 | G14: 1 | H14: =E14*F14*G14 -> 3 | I14: =H14/SUM($H$2:$H$43) -> 0.00025698133
C15: Mang tính lặp lại | D15: Nguồn | E15: 1 | F15: 6 | G15: 4 | H15: =E15*F15*G15 -> 24 | I15: =H15/SUM($H$2:$H$43) -> 0.0020558506
C16: Mang tính lặp lại | D16: Nguồn | E16: 1 | F16: 6 | G16: 5 | H16: =E16*F16*G16 -> 30 | I16: =H16/SUM($H$2:$H$43) -> 0.0025698133
C17: Mang tính tư duy | D17: Nguồn/Lưới | E17: 1 | F17: 6 | G17: 10 | H17: =E17*F17*G17 -> 60 | I17: =H17/SUM($H$2:$H$43) -> 0.0051396265
A18: 5 | B18: Tính toán ngắn mạch tại thanh cái | C18: Mang tính tư duy | D18: Nguồn/Lưới | E18: 1 | F18: 3 | G18: 1 | H18: =E18*F18*G18 -> 3 | I18: =H18/SUM($H$2:$H$43) -> 0.00025698133
C19: Mang tính lặp lại | D19: Nguồn/Lưới | E19: 1 | F19: 6 | G19: 4 | H19: =E19*F19*G19 -> 24 | I19: =H19/SUM($H$2:$H$43) -> 0.0020558506
C20: Mang tính lặp lại | D20: Nguồn/Lưới | E20: 1 | F20: 6 | G20: 5 | H20: =E20*F20*G20 -> 30 | I20: =H20/SUM($H$2:$H$43) -> 0.0025698133
C21: Mang tính tư duy | D21: Nguồn/Lưới | E21: 1 | F21: 6 | G21: 10 | H21: =E21*F21*G21 -> 60 | I21: =H21/SUM($H$2:$H$43) -> 0.0051396265
A22: 6 | B22: Tính toán kháng bù | C22: Mang tính tư duy | D22: Nguồn/Lưới | E22: 1 | F22: 1 | G22: 5 | H22: =E22*F22*G22 -> 5 | I22: =H22/SUM($H$2:$H$43) -> 0.00042830221
C23: Mang tính lặp lại | D23: Nguồn/Lưới | E23: 1 | F23: 3 | G23: 5 | H23: =E23*F23*G23 -> 15 | I23: =H23/SUM($H$2:$H$43) -> 0.0012849066
C24: Mang tính lặp lại | D24: Nguồn/Lưới | E24: 1 | F24: 3 | G24: 5 | H24: =E24*F24*G24 -> 15 | I24: =H24/SUM($H$2:$H$43) -> 0.0012849066
C25: Mang tính tư duy | D25: Đường dây | E25: 1 | F25: 3 | G25: 5 | H25: =E25*F25*G25 -> 15 | I25: =H25/SUM($H$2:$H$43) -> 0.0012849066
A26: 7 | B26: Tính toán ngắn mạch phân bố | C26: Mang tính tư duy | D26: Đường dây | E26: 1 | F26: 1 | G26: 5 | H26: =E26*F26*G26 -> 5 | I26: =H26/SUM($H$2:$H$43) -> 0.00042830221
C27: Mang tính lặp lại | D27: Đường dây | E27: 1 | F27: 3 | G27: 1 | H27: =E27*F27*G27 -> 3 | I27: =H27/SUM($H$2:$H$43) -> 0.00025698133
C28: Mang tính lặp lại | D28: Đường dây | E28: 1 | F28: 3 | G28: 4 | H28: =E28*F28*G28 -> 12 | I28: =H28/SUM($H$2:$H$43) -> 0.0010279253
C29: Mang tính tư duy | D29: Đường dây | E29: 1 | F29: 3 | G29: 10 | H29: =E29*F29*G29 -> 30 | I29: =H29/SUM($H$2:$H$43) -> 0.0025698133
A30: 8 | B30: Tính toán ổn định động | C30: Mang tính tư duy | D30: Nguồn | E30: 1 | F30: 1 | G30: 10 | H30: =E30*F30*G30 -> 10 | I30: =H30/SUM($H$2:$H$43) -> 0.00085660442
C31: Mang tính lặp lại | D31: Nguồn | E31: 1 | F31: 3 | G31: 3 | H31: =E31*F31*G31 -> 9 | I31: =H31/SUM($H$2:$H$43) -> 0.00077094398
C32: Mang tính tư duy | D32: Nguồn | E32: 1 | F32: 3 | G32: 2 | H32: =E32*F32*G32 -> 6 | I32: =H32/SUM($H$2:$H$43) -> 0.00051396265
C33: Mang tính tư duy | D33: Nguồn | E33: 1 | F33: 3 | G33: 5 | H33: =E33*F33*G33 -> 15 | I33: =H33/SUM($H$2:$H$43) -> 0.0012849066
C34: Mang tính lặp lại | D34: Nguồn | E34: 1 | F34: 3 | G34: 5 | H34: =E34*F34*G34 -> 15 | I34: =H34/SUM($H$2:$H$43) -> 0.0012849066
C35: Mang tính tư duy | D35: Nguồn | E35: 1 | F35: 3 | G35: 5 | H35: =E35*F35*G35 -> 15 | I35: =H35/SUM($H$2:$H$43) -> 0.0012849066
A36: 9 | B36: Chỉnh tên các chế độ trong file ZWCad | C36: Mang tính lặp lại | D36: Nguồn/Lưới | E36: 1 | F36: 100 | G36: 5 | H36: =E36*F36*G36 -> 500 | I36: =H36/SUM($H$2:$H$43) -> 0.042830221
A37: 10 | B37: Huy động nguồn | C37: Mang tính tư duy | D37: Nguồn/Lưới | E37: 1 | F37: 6 | G37: 8 | H37: =E37*F37*G37 -> 48 | I37: =H37/SUM($H$2:$H$43) -> 0.0041117012
C38: Mang tính lặp lại | D38: Nguồn/Lưới | E38: 1 | F38: 6 | G38: 2 | H38: =E38*F38*G38 -> 12 | I38: =H38/SUM($H$2:$H$43) -> 0.0010279253
A39: 11 | B39: Tính toán truyền tải liên miền | C39: Mang tính tư duy | D39: Nguồn/Lưới | E39: 1 | F39: 1 | G39: 1 | H39: =E39*F39*G39 -> 1 | I39: =H39/SUM($H$2:$H$43) -> 8.5660442e-05
C40: Mang tính tư duy | D40: Nguồn/Lưới | E40: 1 | F40: 1 | G40: 1 | H40: =E40*F40*G40 -> 1 | I40: =H40/SUM($H$2:$H$43) -> 8.5660442e-05
...

Sheet Sheet4
A1: Loại dự án | C1: Trọng số | D1: Tính chất công việc | E1: Tỉ lệ | F1: Số giờ quy đổi | G1: Tỉ lệ | H1: Sau khi có công cụ hỗ trợ | I1: số dự án | J1: Gốc | P1: Loại dự án | R1: Số giờ mang tính lặp lại | S1: Số giờ mang tính tư duy | U1: Loại dự án | W1: Số giờ mang tính lặp lại | X1: Số giờ mang tính tư duy
A2: Nguồn | B2: Nhiệt điện | C2: =I2/127 -> 0.14173228 | D2: Mang tính tư duy | E2: =1-E3 -> 0.6 | F2: =E2*C2*$F$17 -> 1296 | G2: =1-G3 -> 0.729 | H2: =G2*C2*$F$17 -> 1574.64 | I2: 18 | J2: 18 | P2: Nguồn | Q2: Nhiệt điện | R2: =F3 -> 864 | S2: =F2 -> 1296 | U2: Nguồn | V2: Nhiệt điện | W2: =H3 -> 585.36 | X2: =H2 -> 1574.64
D3: Mang tính lặp lại | E3: =Sheet2!J47 -> 0.4 | F3: =E3*C2*$F$17 -> 864 | G3: =Sheet2!L47 -> 0.271 | H3: =G3*C2*$F$17 -> 585.36 | Q3: Thủy điện | R3: =F5 -> 249 | S3: =F4 -> 351 | V3: Thủy điện | W3: =H5 -> 176.58 | X3: =H4 -> 423.42
B4: Thủy điện | C4: =I4/127 -> 0.039370079 | D4: Mang tính tư duy | E4: =1-E5 -> 0.585 | F4: =E4*C4*$F$17 -> 351 | G4: =1-G5 -> 0.7057 | H4: =G4*C4*$F$17 -> 423.42 | I4: 5 | J4: 4 | Q4: Năng lượng tái tạo | R4: =F7 -> 1137.12 | S4: =F6 -> 1622.88 | V4: Năng lượng tái tạo | W4: =H7 -> 803.712 | X4: =H6 -> 1956.288
D5: Mang tính lặp lại | E5: =Sheet2!F47 -> 0.415 | F5: =E5*C4*$F$17 -> 249 | G5: =Sheet2!H47 -> 0.2943 | H5: =G5*C4*$F$17 -> 176.58 | P5: Lưới | Q5: 500kV | R5: =F9 -> 1466.4 | S5: =F8 -> 1653.6 | U5: Lưới | V5: 500kV | W5: =H9 -> 1004.64 | X5: =H8 -> 2115.36
B6: Năng lượng tái tạo | C6: =I6/127 -> 0.18110236 | D6: Mang tính tư duy | E6: =1-E7 -> 0.588 | F6: =E6*C6*$F$17 -> 1622.88 | G6: =1-G7 -> 0.7088 | H6: =G6*C6*$F$17 -> 1956.288 | I6: 23 | J6: 18 | K6: TĐ tích năng, ĐHN nổi, BESS, giải tỏa CS NLTT, ĐG, ĐMT toàn Q (5) | Q6: 220kV | R6: =F11 -> 2265.6 | S6: =F10 -> 1574.4 | V6: 220kV | W6: =H11 -> 1593.6 | X6: =H10 -> 2246.4
D7: Mang tính lặp lại | E7: =Sheet2!N47 -> 0.412 | F7: =E7*C6*$F$17 -> 1137.12 | G7: =Sheet2!P47 -> 0.2912 | H7: =G7*C6*$F$17 -> 803.712 | Q7: 110kV | R7: =F13 -> 1711.2 | S7: =F12 -> 1048.8 | V7: 110kV | W7: =H13 -> 1203.36 | X7: =H12 -> 1556.64
A8: Lưới | B8: 500kV | C8: =I8/127 -> 0.20472441 | D8: Mang tính tư duy | E8: =1-E9 -> 0.53 | F8: =E8*C8*$F$17 -> 1653.6 | G8: =1-G9 -> 0.678 | H8: =G8*C8*$F$17 -> 2115.36 | I8: 26 | J8: 18 | K8: Lưới VN-lào-cpc, cấp điện Trường sa, tổn thất LTT, HVDC (4) | P8: Tổng | R8: =SUM(R2:R7) -> 7693.32 | S8: =SUM(S2:S7) -> 7546.68 | U8: Tổng | W8: =SUM(W2:W7) -> 5367.252 | X8: =SUM(X2:X7) -> 9872.748
D9: Mang tính lặp lại | E9: =Sheet2!R47 -> 0.47 | F9: =E9*C8*$F$17 -> 1466.4 | G9: =Sheet2!T47 -> 0.322 | H9: =G9*C8*$F$17 -> 1004.64 | K9: LĐ-TT (4)
B10: 220kV | C10: =I10/127 -> 0.2519685 | D10: Mang tính tư duy | E10: =1-E11 -> 0.41 | F10: =E10*C10*$F$17 -> 1574.4 | G10: =1-G11 -> 0.585 | H10: =G10*C10*$F$17 -> 2246.4 | I10: 32 | J10: 28
D11: Mang tính lặp lại | E11: =Sheet2!V47 -> 0.59 | F11: =E11*C10*$F$17 -> 2265.6 | G11: =Sheet2!X47 -> 0.415 | H11: =G11*C10*$F$17 -> 1593.6 | K11: LĐ-TT (4)
B12: 110kV | C12: =I12/127 -> 0.18110236 | D12: Mang tính tư duy | E12: =1-E13 -> 0.38 | F12: =E12*C12*$F$17 -> 1048.8 | G12: =1-G13 -> 0.564 | H12: =G12*C12*$F$17 -> 1556.64 | I12: 23 | J12: 15 | K12: LĐ khác(3)
D13: Mang tính lặp lại | E13: =Sheet2!Z47 -> 0.62 | F13: =E13*C12*$F$17 -> 1711.2 | G13: =Sheet2!AB47 -> 0.436 | H13: =G13*C12*$F$17 -> 1203.36 | K13: LĐ-TT (5)
D14: Tổng số giờ mang tính tư duy | F14: =SUM(F2,F4,F6,F8,F10,F12) -> 7546.68 | H14: =SUM(H2,H4,H6,H8,H10,H12) -> 9872.748
D15: Tổng số giờ mang tính lặp lại | F15: =SUM(F3,F5,F7,F9,F11,F13) -> 7693.32 | H15: =SUM(H3,H5,H7,H9,H11,H13) -> 5367.252
D16: Giảm trên 1 dự án | H16: =(F15-H15)/F17 -> 0.15262913 | K16: BCCN | L16: 8
D17: Tổng số giờ | E17: =Sheet2!AO1 -> 15240 | F17: =Sheet2!AO1 -> 15240 | I17: =SUM(I2:I13) -> 127 | K17: LĐ khác | L17: 3
F18: =52*8*5 -> 2080 | I18: ( số liệu 2020) | K18: LĐ-TT | L18: 14
K19: NN | L19: 1
