Workbook

Sheet GEN0
A1: 113015 | B1: 'GENSAL' | C1: 1 | D1: 5 | E1: 0.05 | F1: 0.2 | G1: 5 | H1: 0 | I1: 1 | J1: 0.75 | K1: 0.4 | L1: 0.22 | M1: 0.1 | N1: 0.11 | O1: 0.62 | P1: / | Q1: /
A2: 113017 | B2: 'GENSAL' | C2: 1 | D2: 5 | E2: 0.05 | F2: 0.2 | G2: 5 | H2: 0 | I2: 1 | J2: 0.75 | K2: 0.4 | L2: 0.22 | M2: 0.1 | N2: 0.11 | O2: 0.62 | P2: / | Q2: /
A3: 126047 | B3: 'GENSAL' | C3: 1 | D3: 5 | E3: 0.05 | F3: 0.2 | G3: 5 | H3: 0 | I3: 1 | J3: 0.75 | K3: 0.4 | L3: 0.22 | M3: 0.1 | N3: 0.11 | O3: 0.62 | P3: / | Q3: /
A4: 213019 | B4: 'GENSAL' | C4: 1 | D4: 5 | E4: 0.05 | F4: 0.2 | G4: 5 | H4: 0 | I4: 1 | J4: 0.75 | K4: 0.4 | L4: 0.22 | M4: 0.1 | N4: 0.11 | O4: 0.62 | P4: / | Q4: /
A5: 213021 | B5: 'GENSAL' | C5: 1 | D5: 6.6 | E5: 0.05 | F5: 0.155 | G5: 2 | H5: 0 | I5: 1.13 | J5: 0.734 | K5: 0.26 | L5: 0.3 | M5: 0.104 | N5: 0.194 | O5: 0.685 | P5: / | Q5: /
A6: 213031 | B6: 'GENSAL' | C6: 1 | D6: 6.6 | E6: 0.05 | F6: 0.155 | G6: 2 | H6: 0 | I6: 1.13 | J6: 0.734 | K6: 0.26 | L6: 0.23 | M6: 0.104 | N6: 0.194 | O6: 0.685 | P6: / | Q6: /
A7: 213041 | B7: 'GENSAL' | C7: 1 | D7: 6.6 | E7: 0.05 | F7: 0.155 | G7: 2 | H7: 0 | I7: 1.13 | J7: 0.734 | K7: 0.26 | L7: 0.23 | M7: 0.104 | N7: 0.194 | O7: 0.685 | P7: / | Q7: /
A8: 213051 | B8: 'GENSAL' | C8: 1 | D8: 9.3 | E8: 0.096 | F8: 0.075 | G8: 3.42 | H8: 0 | I8: 1.15 | J8: 0.748 | K8: 0.32 | L8: 0.32 | M8: 0.13 | N8: 0.245 | O8: 0.77 | P8: / | Q8: /
A9: 216011 | B9: 'GENSAL' | C9: 1 | D9: 5 | E9: 0.05 | F9: 0.2 | G9: 5 | H9: 0 | I9: 1 | J9: 0.75 | K9: 0.4 | L9: 0.23 | M9: 0.1 | N9: 0.11 | O9: 0.62 | P9: / | Q9: /
A10: 821012 | B10: 'GENROU' | C10: 1 | D10: 6.5 | E10: 0.06 | F10: 0.2 | G10: 0.05 | H10: 4 | I10: 0 | J10: 1.8 | K10: 1.75 | L10: 0.6 | M10: 0.8 | N10: 0.3 | O10: 0.15 | P10: 0.09 | Q10: 0.38 | R10: / | S10: /
A11: 910011 | B11: 'GENSAL' | C11: 1 | D11: 7.2 | E11: 0.123 | F11: 0.075 | G11: 4.677 | H11: 0 | I11: 0.87 | J11: 0.58 | K11: 0.27 | L11: 0.2 | M11: 0.116 | N11: 0.178 | O11: 0.592 | P11: / | Q11: /
A12: 912011 | B12: 'GENROU' | C12: 1 | D12: 4.76 | E12: 0.04 | F12: 0.426 | G12: 0.067 | H12: 3.4 | I12: 0 | J12: 1.825 | K12: 1.751 | L12: 0.275 | M12: 0.417 | N12: 0.135 | O12: 0.169 | P12: 0.09 | Q12: 0.4 | R12: / | S12: /
A13: 912012 | B13: 'GENROU' | C13: 1 | D13: 4.76 | E13: 0.04 | F13: 0.426 | G13: 0.067 | H13: 3.4 | I13: 0 | J13: 1.825 | K13: 1.751 | L13: 0.275 | M13: 0.417 | N13: 0.135 | O13: 0.169 | P13: 0.09 | Q13: 0.4 | R13: / | S13: /
A14: 913011 | B14: 'GENSAL' | C14: 1 | D14: 7.83 | E14: 0.057 | F14: 0.07 | G14: 4 | H14: 0.5 | I14: 1.083 | J14: 0.83 | K14: 0.375 | L14: 0.206 | M14: 0.107 | N14: 0.13 | O14: 0.436 | P14: / | Q14: /
A15: 913031 | B15: 'GENSAL' | C15: 1 | D15: 6.6 | E15: 0.05 | F15: 0.155 | G15: 2 | H15: 0 | I15: 1.13 | J15: 0.734 | K15: 0.26 | L15: 0.23 | M15: 0.104 | N15: 0.194 | O15: 0.685 | P15: / | Q15: /
A16: 913041 | B16: 'GENSAL' | C16: 1 | D16: 6.6 | E16: 0.05 | F16: 0.155 | G16: 2 | H16: 0 | I16: 1.13 | J16: 0.734 | K16: 0.26 | L16: 0.23 | M16: 0.104 | N16: 0.194 | O16: 0.685 | P16: / | Q16: /
A17: 913051 | B17: 'GENSAL' | C17: 1 | D17: 6.6 | E17: 0.05 | F17: 0.155 | G17: 2 | H17: 0 | I17: 1.13 | J17: 0.734 | K17: 0.26 | L17: 0.18 | M17: 0.104 | N17: 0.194 | O17: 0.685 | P17: / | Q17: /
A18: 913061 | B18: 'GENSAL' | C18: 1 | D18: 6.6 | E18: 0.05 | F18: 0.155 | G18: 2 | H18: 0 | I18: 1.13 | J18: 0.734 | K18: 0.26 | L18: 0.18 | M18: 0.104 | N18: 0.194 | O18: 0.685 | P18: / | Q18: /
A19: 914011 | B19: 'GENSAL' | C19: 1 | D19: 6.6 | E19: 0.05 | F19: 0.155 | G19: 2 | H19: 0 | I19: 1.13 | J19: 0.734 | K19: 0.26 | L19: 0.16 | M19: 0.104 | N19: 0.194 | O19: 0.685 | P19: / | Q19: /
A20: 914012 | B20: 'GENSAL' | C20: 1 | D20: 6.6 | E20: 0.05 | F20: 0.155 | G20: 2 | H20: 0 | I20: 1.13 | J20: 0.734 | K20: 0.26 | L20: 0.16 | M20: 0.104 | N20: 0.194 | O20: 0.685 | P20: / | Q20: /
A21: 914013 | B21: 'GENSAL' | C21: 1 | D21: 6.6 | E21: 0.05 | F21: 0.155 | G21: 2 | H21: 0 | I21: 1.13 | J21: 0.734 | K21: 0.26 | L21: 0.16 | M21: 0.104 | N21: 0.194 | O21: 0.685 | P21: / | Q21: /
A22: 915001 | B22: 'GENSAL' | C22: 1 | D22: 7.2 | E22: 0.123 | F22: 0.075 | G22: 4.677 | H22: 0 | I22: 0.87 | J22: 0.58 | K22: 0.27 | L22: 0.165 | M22: 0.116 | N22: 0.178 | O22: 0.592 | P22: / | Q22: /
A23: 915002 | B23: 'GENSAL' | C23: 1 | D23: 7.2 | E23: 0.123 | F23: 0.075 | G23: 4.677 | H23: 0 | I23: 0.87 | J23: 0.58 | K23: 0.27 | L23: 0.165 | M23: 0.116 | N23: 0.178 | O23: 0.592 | P23: / | Q23: /
A24: 915007 | B24: 'GENSAL' | C24: 1 | D24: 7.2 | E24: 0.123 | F24: 0.075 | G24: 4.677 | H24: 0 | I24: 0.87 | J24: 0.58 | K24: 0.27 | L24: 0.165 | M24: 0.116 | N24: 0.178 | O24: 0.592 | P24: / | Q24: /
A25: 915109 | B25: 'GENSAL' | C25: 1 | D25: 6.6 | E25: 0.05 | F25: 0.155 | G25: 2 | H25: 0 | I25: 1.13 | J25: 0.734 | K25: 0.26 | L25: 0.16 | M25: 0.104 | N25: 0.194 | O25: 0.685 | P25: / | Q25: /
... A80: 920022 | B80: 'GENSAL' | C80: 1 | D80: 7.83 | E80: 0.057 | F80: 0.07 | G80: 4 | H80: 0.5 | I80: 1.083 | J80: 0.83 | K80: 0.375 | L80: 0.24 | M80: 0.107 | N80: 0.13 | O80: 0.436 | P80: / | Q80: /
A81: 922011 | B81: 'GENROU' | C81: 1 | D81: 6.9 | E81: 0.199 | F81: 0.45 | G81: 0.07 | H81: 3.8 | I81: 0 | J81: 2.3 | K81: 2.21 | L81: 0.29 | M81: 0.46 | N81: 0.17 | O81: 0.167 | P81: 0.08 | Q81: 0.56 | R81: / | S81: /
A82: 922012 | B82: 'GENROU' | C82: 1 | D82: 6.9 | E82: 0.199 | F82: 0.45 | G82: 0.07 | H82: 3.8 | I82: 0 | J82: 2.3 | K82: 2.21 | L82: 0.29 | M82: 0.46 | N82: 0.17 | O82: 0.167 | P82: 0.08 | Q82: 0.56 | R82: / | S82: /
A83: 923011 | B83: 'GENSAL' | C83: 1 | D83: 7.83 | E83: 0.057 | F83: 0.07 | G83: 4 | H83: 0.5 | I83: 1.083 | J83: 0.83 | K83: 0.375 | L83: 0.262 | M83: 0.107 | N83: 0.13 | O83: 0.436 | P83: / | Q83: /
A84: 923012 | B84: 'GENSAL' | C84: 1 | D84: 7.83 | E84: 0.057 | F84: 0.07 | G84: 4 | H84: 0.5 | I84: 1.083 | J84: 0.83 | K84: 0.375 | L84: 0.262 | M84: 0.107 | N84: 0.13 | O84: 0.436 | P84: / | Q84: /
A85: 923013 | B85: 'GENSAL' | C85: 1 | D85: 7.83 | E85: 0.057 | F85: 0.07 | G85: 4 | H85: 0.5 | I85: 1.083 | J85: 0.83 | K85: 0.375 | L85: 0.262 | M85: 0.107 | N85: 0.13 | O85: 0.436 | P85: / | Q85: /
A86: 923014 | B86: 'GENSAL' | C86: 1 | D86: 7.83 | E86: 0.057 | F86: 0.07 | G86: 4 | H86: 0.5 | I86: 1.083 | J86: 0.83 | K86: 0.375 | L86: 0.262 | M86: 0.107 | N86: 0.13 | O86: 0.436 | P86: / | Q86: /
A87: 923015 | B87: 'GENSAL' | C87: 1 | D87: 7.83 | E87: 0.057 | F87: 0.07 | G87: 4 | H87: 0.5 | I87: 1.083 | J87: 0.83 | K87: 0.375 | L87: 0.262 | M87: 0.107 | N87: 0.13 | O87: 0.436 | P87: / | Q87: /
A88: 923016 | B88: 'GENSAL' | C88: 1 | D88: 7.83 | E88: 0.057 | F88: 0.07 | G88: 4 | H88: 0.5 | I88: 1.083 | J88: 0.83 | K88: 0.375 | L88: 0.262 | M88: 0.107 | N88: 0.13 | O88: 0.436 | P88: / | Q88: /
A89: 923017 | B89: 'GENSAL' | C89: 1 | D89: 7.83 | E89: 0.057 | F89: 0.07 | G89: 4 | H89: 0.5 | I89: 1.083 | J89: 0.83 | K89: 0.375 | L89: 0.262 | M89: 0.107 | N89: 0.13 | O89: 0.436 | P89: / | Q89: /
A90: 923018 | B90: 'GENSAL' | C90: 1 | D90: 7.83 | E90: 0.057 | F90: 0.07 | G90: 4 | H90: 0.5 | I90: 1.083 | J90: 0.83 | K90: 0.375 | L90: 0.262 | M90: 0.107 | N90: 0.13 | O90: 0.436 | P90: / | Q90: /
A91: 924001 | B91: 'GENROU' | C91: 1 | D91: 6.9 | E91: 0.199 | F91: 0.45 | G91: 0.07 | H91: 3.8 | I91: 0 | J91: 2.3 | K91: 2.21 | L91: 0.29 | M91: 0.46 | N91: 0.22 | O91: 0.167 | P91: 0.08 | Q91: 0.56 | R91: / | S91: /
A92: 924002 | B92: 'GENROU' | C92: 1 | D92: 6.9 | E92: 0.199 | F92: 0.45 | G92: 0.07 | H92: 3.8 | I92: 0 | J92: 2.3 | K92: 2.21 | L92: 0.29 | M92: 0.46 | N92: 0.22 | O92: 0.167 | P92: 0.08 | Q92: 0.56 | R92: / | S92: /
A93: 924002 | B93: 'GENROU' | C93: 2 | D93: 6.9 | E93: 0.199 | F93: 0.45 | G93: 0.07 | H93: 3.8 | I93: 0 | J93: 2.3 | K93: 2.21 | L93: 0.29 | M93: 0.46 | N93: 0.22 | O93: 0.167 | P93: 0.08 | Q93: 0.56 | R93: / | S93: /
A94: 926011 | B94: 'GENROU' | C94: 1 | D94: 4.76 | E94: 0.04 | F94: 0.426 | G94: 0.067 | H94: 3.4 | I94: 0 | J94: 1.825 | K94: 1.751 | L94: 0.275 | M94: 0.417 | N94: 0.206 | O94: 0.169 | P94: 0.09 | Q94: 0.4 | R94: / | S94: /
...

Sheet AVR0
A1: 113015 | B1: 'ESST4B' | C1: 1 | D1: 0 | E1: 15 | F1: 15 | G1: 5 | H1: -0.87 | I1: 0 | J1: 1 | K1: 0 | L1: 99 | M1: -99 | N1: 0 | O1: 9.3 | P1: 0 | Q1: 11.63 | R1: 0.113 | S1: 0.124 | T1: 0 | U1: / | V1: /
A2: 113017 | B2: 'ESST4B' | C2: 1 | D2: 0 | E2: 15 | F2: 15 | G2: 5 | H2: -0.87 | I2: 0 | J2: 1 | K2: 0 | L2: 99 | M2: -99 | N2: 0 | O2: 9.3 | P2: 0 | Q2: 11.63 | R2: 0.113 | S2: 0.124 | T2: 0 | U2: / | V2: /
A3: 126047 | B3: 'ESST4B' | C3: 1 | D3: 0 | E3: 15 | F3: 15 | G3: 5 | H3: -0.87 | I3: 0 | J3: 1 | K3: 0 | L3: 99 | M3: -99 | N3: 0 | O3: 9.3 | P3: 0 | Q3: 11.63 | R3: 0.113 | S3: 0.124 | T3: 0 | U3: / | V3: /
A4: 213019 | B4: 'ESST4B' | C4: 1 | D4: 0 | E4: 15 | F4: 15 | G4: 5 | H4: -0.87 | I4: 0 | J4: 1 | K4: 0 | L4: 99 | M4: -99 | N4: 0 | O4: 9.3 | P4: 0 | Q4: 11.63 | R4: 0.113 | S4: 0.124 | T4: 0 | U4: / | V4: /
A5: 213021 | B5: 'EXAC4' | C5: 1 | D5: 0 | E5: 10 | F5: -10 | G5: 1 | H5: 10 | I5: 200 | J5: 0.015 | K5: 5.64 | L5: -4.53 | M5: 0 | N5: / | O5: /
A6: 213031 | B6: 'ESST4B' | C6: 1 | D6: 0 | E6: 15 | F6: 15 | G6: 5 | H6: -0.87 | I6: 0 | J6: 1 | K6: 0 | L6: 99 | M6: -99 | N6: 0 | O6: 9.3 | P6: 0 | Q6: 11.63 | R6: 0.113 | S6: 0.124 | T6: 0 | U6: / | V6: /
A7: 213041 | B7: 'ESST4B' | C7: 1 | D7: 0 | E7: 15 | F7: 15 | G7: 5 | H7: -0.87 | I7: 0 | J7: 1 | K7: 0 | L7: 99 | M7: -99 | N7: 0 | O7: 9.3 | P7: 0 | Q7: 11.63 | R7: 0.113 | S7: 0.124 | T7: 0 | U7: / | V7: /
A8: 213051 | B8: 'ESST4B' | C8: 1 | D8: 0 | E8: 15 | F8: 15 | G8: 5 | H8: -0.87 | I8: 0 | J8: 1 | K8: 0 | L8: 99 | M8: -99 | N8: 0 | O8: 9.3 | P8: 0 | Q8: 11.63 | R8: 0.113 | S8: 0.124 | T8: 0 | U8: / | V8: /
A9: 216011 | B9: 'ESST4B' | C9: 1 | D9: 0 | E9: 15 | F9: 15 | G9: 5 | H9: -0.87 | I9: 0 | J9: 1 | K9: 0 | L9: 99 | M9: -99 | N9: 0 | O9: 9.3 | P9: 0 | Q9: 11.63 | R9: 0.113 | S9: 0.124 | T9: 0 | U9: / | V9: /
A10: 821012 | B10: 'ESST4B' | C10: 1 | D10: 0 | E10: 15 | F10: 15 | G10: 5 | H10: -0.87 | I10: 0 | J10: 1 | K10: 0 | L10: 99 | M10: -99 | N10: 0 | O10: 9.3 | P10: 0 | Q10: 11.63 | R10: 0.113 | S10: 0.124 | T10: 0 | U10: / | V10: /
A11: 910011 | B11: 'ESST4B' | C11: 1 | D11: 0 | E11: 10.75 | F11: 10.75 | G11: 5 | H11: -0.87 | I11: 0 | J11: 1 | K11: 0 | L11: 99 | M11: -99 | N11: 0 | O11: 9.3 | P11: 0 | Q11: 11.63 | R11: 0.113 | S11: 0.124 | T11: 0 | U11: / | V11: /
A12: 912011 | B12: 'ESST4B' | C12: 1 | D12: 0 | E12: 15 | F12: 15 | G12: 5 | H12: -0.87 | I12: 0 | J12: 1 | K12: 0 | L12: 99 | M12: -99 | N12: 0 | O12: 9.3 | P12: 0 | Q12: 11.63 | R12: 0.113 | S12: 0.124 | T12: 0 | U12: / | V12: /
A13: 912012 | B13: 'ESST4B' | C13: 1 | D13: 0 | E13: 15 | F13: 15 | G13: 5 | H13: -0.87 | I13: 0 | J13: 1 | K13: 0 | L13: 99 | M13: -99 | N13: 0 | O13: 9.3 | P13: 0 | Q13: 11.63 | R13: 0.113 | S13: 0.124 | T13: 0 | U13: / | V13: /
A14: 913011 | B14: 'ESST4B' | C14: 1 | D14: 0 | E14: 10.75 | F14: 10.75 | G14: 5 | H14: -0.87 | I14: 0 | J14: 1 | K14: 0 | L14: 99 | M14: -99 | N14: 0 | O14: 9.3 | P14: 0 | Q14: 11.63 | R14: 0.113 | S14: 0.124 | T14: 0 | U14: / | V14: /
A15: 913031 | B15: 'ESST4B' | C15: 1 | D15: 0 | E15: 10.75 | F15: 10.75 | G15: 5 | H15: -0.87 | I15: 0 | J15: 1 | K15: 0 | L15: 99 | M15: -99 | N15: 0 | O15: 9.3 | P15: 0 | Q15: 11.63 | R15: 0.113 | S15: 0.124 | T15: 0 | U15: / | V15: /
A16: 913041 | B16: 'ESST4B' | C16: 1 | D16: 0 | E16: 10.75 | F16: 10.75 | G16: 5 | H16: -0.87 | I16: 0 | J16: 1 | K16: 0 | L16: 99 | M16: -99 | N16: 0 | O16: 9.3 | P16: 0 | Q16: 11.63 | R16: 0.113 | S16: 0.124 | T16: 0 | U16: / | V16: /
A17: 913051 | B17: 'ESST4B' | C17: 1 | D17: 0 | E17: 10.75 | F17: 10.75 | G17: 5 | H17: -0.87 | I17: 0 | J17: 1 | K17: 0 | L17: 99 | M17: -99 | N17: 0 | O17: 9.3 | P17: 0 | Q17: 11.63 | R17: 0.113 | S17: 0.124 | T17: 0 | U17: / | V17: /
A18: 913061 | B18: 'ESST4B' | C18: 1 | D18: 0 | E18: 10.75 | F18: 10.75 | G18: 5 | H18: -0.87 | I18: 0 | J18: 1 | K18: 0 | L18: 99 | M18: -99 | N18: 0 | O18: 9.3 | P18: 0 | Q18: 11.63 | R18: 0.113 | S18: 0.124 | T18: 0 | U18: / | V18: /
A19: 914011 | B19: 'EXAC4' | C19: 1 | D19: 0 | E19: 10 | F19: -10 | G19: 1 | H19: 10 | I19: 200 | J19: 0.015 | K19: 5.64 | L19: -4.53 | M19: 0 | N19: / | O19: /
A20: 914012 | B20: 'EXAC4' | C20: 1 | D20: 0 | E20: 10 | F20: -10 | G20: 1 | H20: 10 | I20: 200 | J20: 0.015 | K20: 5.64 | L20: -4.53 | M20: 0 | N20: / | O20: /
A21: 914013 | B21: 'EXAC4' | C21: 1 | D21: 0 | E21: 10 | F21: -10 | G21: 1 | H21: 10 | I21: 200 | J21: 0.015 | K21: 5.64 | L21: -4.53 | M21: 0 | N21: / | O21: /
A22: 915001 | B22: 'ESST4B' | C22: 1 | D22: 0 | E22: 10.75 | F22: 10.75 | G22: 5 | H22: -0.87 | I22: 0 | J22: 1 | K22: 0 | L22: 99 | M22: -99 | N22: 0 | O22: 9.3 | P22: 0 | Q22: 11.63 | R22: 0.113 | S22: 0.124 | T22: 0 | U22: / | V22: /
A23: 915002 | B23: 'ESST4B' | C23: 1 | D23: 0 | E23: 10.75 | F23: 10.75 | G23: 5 | H23: -0.87 | I23: 0 | J23: 1 | K23: 0 | L23: 99 | M23: -99 | N23: 0 | O23: 9.3 | P23: 0 | Q23: 11.63 | R23: 0.113 | S23: 0.124 | T23: 0 | U23: / | V23: /
A24: 915007 | B24: 'ESST4B' | C24: 1 | D24: 0 | E24: 10.75 | F24: 10.75 | G24: 5 | H24: -0.87 | I24: 0 | J24: 1 | K24: 0 | L24: 99 | M24: -99 | N24: 0 | O24: 9.3 | P24: 0 | Q24: 11.63 | R24: 0.113 | S24: 0.124 | T24: 0 | U24: / | V24: /
A25: 915109 | B25: 'EXAC4' | C25: 1 | D25: 0 | E25: 0.2 | F25: -0.199 | G25: 0 | H25: 5 | I25: 250 | J25: 0.05 | K25: 5.64 | L25: 0 | M25: 0 | N25: / | O25: /
A26: 915208 | B26: 'EXAC4' | C26: 1 | D26: 0 | E26: 0.2 | F26: -0.199 | G26: 0 | H26: 5 | I26: 250 | J26: 0.05 | K26: 5.64 | L26: 0 | M26: 0 | N26: / | O26: /
A27: 915209 | B27: 'EXAC4' | C27: 1 | D27: 0 | E27: 0.2 | F27: -0.199 | G27: 0 | H27: 5 | I27: 250 | J27: 0.05 | K27: 5.64 | L27: 0 | M27: 0 | N27: / | O27: /
A28: 915211 | B28: 'EXAC4' | C28: 1 | D28: 0 | E28: 0.2 | F28: -0.199 | G28: 0 | H28: 5 | I28: 250 | J28: 0.05 | K28: 5.64 | L28: 0 | M28: 0 | N28: / | O28: /
A29: 915212 | B29: 'EXAC4' | C29: 1 | D29: 0 | E29: 0.2 | F29: -0.199 | G29: 0 | H29: 5 | I29: 250 | J29: 0.05 | K29: 5.64 | L29: 0 | M29: 0 | N29: / | O29: /
A30: 915213 | B30: 'EXAC4' | C30: 1 | D30: 0 | E30: 0.2 | F30: -0.199 | G30: 0 | H30: 5 | I30: 250 | J30: 0.05 | K30: 5.64 | L30: 0 | M30: 0 | N30: / | O30: /
A31: 915214 | B31: 'EXAC4' | C31: 1 | D31: 0 | E31: 0.2 | F31: -0.199 | G31: 0 | H31: 5 | I31: 250 | J31: 0.05 | K31: 5.64 | L31: 0 | M31: 0 | N31: / | O31: /
A32: 915237 | B32: 'EXAC4' | C32: 1 | D32: 0 | E32: 0.2 | F32: -0.199 | G32: 0 | H32: 5 | I32: 250 | J32: 0.05 | K32: 5.64 | L32: 0 | M32: 0 | N32: / | O32: /
A33: 915238 | B33: 'EXAC4' | C33: 1 | D33: 0 | E33: 0.2 | F33: -0.199 | G33: 0 | H33: 5 | I33: 250 | J33: 0.05 | K33: 5.64 | L33: 0 | M33: 0 | N33: / | O33: /
A34: 915239 | B34: 'EXAC4' | C34: 1 | D34: 0 | E34: 0.2 | F34: -0.199 | G34: 0 | H34: 5 | I34: 250 | J34: 0.05 | K34: 5.64 | L34: 0 | M34: 0 | N34: / | O34: /
A35: 916011 | B35: 'ESST4B' | C35: 1 | D35: 0 | E35: 10.75 | F35: 10.75 | G35: 5 | H35: -0.87 | I35: 0 | J35: 1 | K35: 0 | L35: 99 | M35: -99 | N35: 0 | O35: 9.3 | P35: 0 | Q35: 11.63 | R35: 0.113 | S35: 0.124 | T35: 0 | U35: / | V35: /
A36: 916012 | B36: 'ESST4B' | C36: 1 | D36: 0 | E36: 10.75 | F36: 10.75 | G36: 5 | H36: -0.87 | I36: 0 | J36: 1 | K36: 0 | L36: 99 | M36: -99 | N36: 0 | O36: 9.3 | P36: 0 | Q36: 11.63 | R36: 0.113 | S36: 0.124 | T36: 0 | U36: / | V36: /
A37: 916019 | B37: 'ESST4B' | C37: 1 | D37: 0 | E37: 10.75 | F37: 10.75 | G37: 5 | H37: -0.87 | I37: 0 | J37: 1 | K37: 0 | L37: 99 | M37: -99 | N37: 0 | O37: 9.3 | P37: 0 | Q37: 11.63 | R37: 0.113 | S37: 0.124 | T37: 0 | U37: / | V37: /
A38: 916023 | B38: 'ESST4B' | C38: 1 | D38: 0 | E38: 10.75 | F38: 10.75 | G38: 5 | H38: -0.87 | I38: 0 | J38: 1 | K38: 0 | L38: 99 | M38: -99 | N38: 0 | O38: 9.3 | P38: 0 | Q38: 11.63 | R38: 0.113 | S38: 0.124 | T38: 0 | U38: / | V38: /
A39: 916031 | B39: 'ESST4B' | C39: 1 | D39: 0 | E39: 15 | F39: 15 | G39: 5 | H39: -0.87 | I39: 0 | J39: 1 | K39: 0 | L39: 99 | M39: -99 | N39: 0 | O39: 9.3 | P39: 0 | Q39: 11.63 | R39: 0.113 | S39: 0.124 | T39: 0 | U39: / | V39: /
A40: 916032 | B40: 'ESST4B' | C40: 1 | D40: 0 | E40: 15 | F40: 15 | G40: 5 | H40: -0.87 | I40: 0 | J40: 1 | K40: 0 | L40: 99 | M40: -99 | N40: 0 | O40: 9.3 | P40: 0 | Q40: 11.63 | R40: 0.113 | S40: 0.124 | T40: 0 | U40: / | V40: /
...

Sheet GOV0
A1: 113015 | B1: 'HYGOV' | C1: 1 | D1: 0.03 | E1: 0.18 | F1: 6.64 | G1: 0.05 | H1: 0.5 | I1: 0.15 | J1: 1 | K1: 0 | L1: 1.66 | M1: 1.41 | N1: 0.499 | O1: 0.06 | P1: / | Q1: /
A2: 113017 | B2: 'HYGOV' | C2: 1 | D2: 0.03 | E2: 0.18 | F2: 6.64 | G2: 0.05 | H2: 0.5 | I2: 0.15 | J2: 1 | K2: 0 | L2: 1.66 | M2: 1.41 | N2: 0.499 | O2: 0.06 | P2: / | Q2: /
A3: 126047 | B3: 'HYGOV' | C3: 1 | D3: 0.03 | E3: 0.18 | F3: 6.64 | G3: 0.05 | H3: 0.5 | I3: 0.15 | J3: 1 | K3: 0 | L3: 1.66 | M3: 1.41 | N3: 0.499 | O3: 0.06 | P3: / | Q3: /
A4: 213019 | B4: 'HYGOV' | C4: 1 | D4: 0.03 | E4: 0.18 | F4: 6.64 | G4: 0.05 | H4: 0.5 | I4: 0.15 | J4: 1 | K4: -1 | L4: 1.66 | M4: 1.41 | N4: 0.499 | O4: 0.06 | P4: / | Q4: /
A5: 213021 | B5: 'HYGOV' | C5: 1 | D5: 0.06 | E5: 0.4 | F5: 3 | G5: 0.099 | H5: 0.4 | I5: 0.15 | J5: 1 | K5: 0.1 | L5: 1.35 | M5: 1.4 | N5: 0.1 | O5: 0.1 | P5: / | Q5: /
A6: 213031 | B6: 'HYGOV' | C6: 1 | D6: 0.06 | E6: 0.4 | F6: 3 | G6: 0.099 | H6: 0.4 | I6: 0.15 | J6: 1 | K6: 0.1 | L6: 1.35 | M6: 1.4 | N6: 0.1 | O6: 0.1 | P6: / | Q6: /
A7: 213041 | B7: 'HYGOV' | C7: 1 | D7: 0.06 | E7: 0.4 | F7: 3 | G7: 0.099 | H7: 0.4 | I7: 0.15 | J7: 1 | K7: 0.1 | L7: 1.35 | M7: 1.4 | N7: 0.1 | O7: 0.1 | P7: / | Q7: /
A8: 213051 | B8: 'HYGOV' | C8: 1 | D8: 0.06 | E8: 0.4 | F8: 3 | G8: 0.099 | H8: 0.4 | I8: 0.15 | J8: 1 | K8: 0.1 | L8: 1.35 | M8: 1.4 | N8: 0.1 | O8: 0.1 | P8: / | Q8: /
A9: 216011 | B9: 'HYGOV' | C9: 1 | D9: 0.03 | E9: 0.18 | F9: 6.64 | G9: 0.05 | H9: 0.5 | I9: 0.15 | J9: 1 | K9: 0 | L9: 1.66 | M9: 1.41 | N9: 0.499 | O9: 0.06 | P9: / | Q9: /
A10: 821012 | B10: 'TGOV1' | C10: 1 | D10: 0.05 | E10: 0.05 | F10: 0.9 | G10: 0.3 | H10: 3 | I10: 9 | J10: 0 | K10: / | L10: /
A11: 910011 | B11: 'HYGOV' | C11: 1 | D11: 0.03 | E11: 0.18 | F11: 6.64 | G11: 0.05 | H11: 0.5 | I11: 0.15 | J11: 1 | K11: 0 | L11: 1.66 | M11: 1.41 | N11: 0.499 | O11: 0.06 | P11: / | Q11: /
A12: 912011 | B12: 'TGOV1' | C12: 1 | D12: 0.03 | E12: 0.499 | F12: 1 | G12: 0 | H12: 4 | I12: 9 | J12: 0.1 | K12: / | L12: /
A13: 912012 | B13: 'TGOV1' | C13: 1 | D13: 0.03 | E13: 0.499 | F13: 1 | G13: 0 | H13: 4 | I13: 9 | J13: 0.1 | K13: / | L13: /
A14: 913011 | B14: 'HYGOV' | C14: 1 | D14: 0.03 | E14: 0.18 | F14: 6.64 | G14: 0.05 | H14: 0.5 | I14: 0.15 | J14: 1 | K14: 0 | L14: 1.66 | M14: 1.41 | N14: 0.499 | O14: 0.06 | P14: / | Q14: /
A15: 913031 | B15: 'HYGOV' | C15: 1 | D15: 0.06 | E15: 0.4 | F15: 3 | G15: 0.099 | H15: 0.4 | I15: 0.15 | J15: 1 | K15: 0.1 | L15: 1.35 | M15: 1.4 | N15: 0.1 | O15: 0.1 | P15: / | Q15: /
A16: 913041 | B16: 'HYGOV' | C16: 1 | D16: 0.06 | E16: 0.4 | F16: 3 | G16: 0.099 | H16: 0.4 | I16: 0.15 | J16: 1 | K16: 0.1 | L16: 1.35 | M16: 1.4 | N16: 0.1 | O16: 0.1 | P16: / | Q16: /
A17: 913051 | B17: 'HYGOV' | C17: 1 | D17: 0.06 | E17: 0.4 | F17: 3 | G17: 0.099 | H17: 0.4 | I17: 0.15 | J17: 1 | K17: 0.1 | L17: 1.35 | M17: 1.4 | N17: 0.1 | O17: 0.1 | P17: / | Q17: /
A18: 913061 | B18: 'HYGOV' | C18: 1 | D18: 0.06 | E18: 0.4 | F18: 3 | G18: 0.099 | H18: 0.4 | I18: 0.15 | J18: 1 | K18: 0.1 | L18: 1.35 | M18: 1.4 | N18: 0.1 | O18: 0.1 | P18: / | Q18: /
A19: 914011 | B19: 'HYGOV' | C19: 1 | D19: 0.06 | E19: 0.4 | F19: 3 | G19: 0.099 | H19: 0.4 | I19: 0.15 | J19: 1 | K19: 0.1 | L19: 1.35 | M19: 1.4 | N19: 0.1 | O19: 0.1 | P19: / | Q19: /
A20: 914012 | B20: 'HYGOV' | C20: 1 | D20: 0.06 | E20: 0.4 | F20: 3 | G20: 0.099 | H20: 0.4 | I20: 0.15 | J20: 1 | K20: 0.1 | L20: 1.35 | M20: 1.4 | N20: 0.1 | O20: 0.1 | P20: / | Q20: /
A21: 914013 | B21: 'HYGOV' | C21: 1 | D21: 0.06 | E21: 0.4 | F21: 3 | G21: 0.099 | H21: 0.4 | I21: 0.15 | J21: 1 | K21: 0.1 | L21: 1.35 | M21: 1.4 | N21: 0.1 | O21: 0.1 | P21: / | Q21: /
A22: 915001 | B22: 'HYGOV' | C22: 1 | D22: 0.06 | E22: 0.4 | F22: 3 | G22: 0.099 | H22: 0.4 | I22: 0.15 | J22: 1 | K22: 0.1 | L22: 1.35 | M22: 1.4 | N22: 0.1 | O22: 0.1 | P22: / | Q22: /
A23: 915002 | B23: 'HYGOV' | C23: 1 | D23: 0.06 | E23: 0.4 | F23: 3 | G23: 0.099 | H23: 0.4 | I23: 0.15 | J23: 1 | K23: 0.1 | L23: 1.35 | M23: 1.4 | N23: 0.1 | O23: 0.1 | P23: / | Q23: /
A24: 915007 | B24: 'HYGOV' | C24: 1 | D24: 0.06 | E24: 0.4 | F24: 3 | G24: 0.099 | H24: 0.4 | I24: 0.15 | J24: 1 | K24: 0.1 | L24: 1.35 | M24: 1.4 | N24: 0.1 | O24: 0.1 | P24: / | Q24: /
A25: 915109 | B25: 'HYGOV' | C25: 1 | D25: 0.06 | E25: 0.4 | F25: 3 | G25: 0.099 | H25: 0.4 | I25: 0.15 | J25: 1 | K25: 0.1 | L25: 1.35 | M25: 1.4 | N25: 0.1 | O25: 0.1 | P25: / | Q25: /
... A80: 920022 | B80: 'HYGOV' | C80: 1 | D80: 0.03 | E80: 0.18 | F80: 6.64 | G80: 0.05 | H80: 0.5 | I80: 0.15 | J80: 1 | K80: 0 | L80: 1.66 | M80: 1.41 | N80: 0.499 | O80: 0.06 | P80: / | Q80: /
A81: 922011 | B81: 'TGOV1' | C81: 1 | D81: 0.03 | E81: 0.499 | F81: 1 | G81: 0 | H81: 4 | I81: 9 | J81: 0.1 | K81: / | L81: /
A82: 922012 | B82: 'TGOV1' | C82: 1 | D82: 0.03 | E82: 0.499 | F82: 1 | G82: 0 | H82: 4 | I82: 9 | J82: 0.1 | K82: / | L82: /
A83: 923011 | B83: 'HYGOV' | C83: 1 | D83: 0.03 | E83: 0.18 | F83: 6.64 | G83: 0.05 | H83: 0.5 | I83: 0.15 | J83: 1 | K83: 0 | L83: 1.66 | M83: 1.41 | N83: 0.499 | O83: 0.06 | P83: / | Q83: /
A84: 923012 | B84: 'HYGOV' | C84: 1 | D84: 0.03 | E84: 0.18 | F84: 6.64 | G84: 0.05 | H84: 0.5 | I84: 0.15 | J84: 1 | K84: 0 | L84: 1.66 | M84: 1.41 | N84: 0.499 | O84: 0.06 | P84: / | Q84: /
A85: 923013 | B85: 'HYGOV' | C85: 1 | D85: 0.03 | E85: 0.18 | F85: 6.64 | G85: 0.05 | H85: 0.5 | I85: 0.15 | J85: 1 | K85: 0 | L85: 1.66 | M85: 1.41 | N85: 0.499 | O85: 0.06 | P85: / | Q85: /
A86: 923014 | B86: 'HYGOV' | C86: 1 | D86: 0.03 | E86: 0.18 | F86: 6.64 | G86: 0.05 | H86: 0.5 | I86: 0.15 | J86: 1 | K86: 0 | L86: 1.66 | M86: 1.41 | N86: 0.499 | O86: 0.06 | P86: / | Q86: /
A87: 923015 | B87: 'HYGOV' | C87: 1 | D87: 0.03 | E87: 0.18 | F87: 6.64 | G87: 0.05 | H87: 0.5 | I87: 0.15 | J87: 1 | K87: 0 | L87: 1.66 | M87: 1.41 | N87: 0.499 | O87: 0.06 | P87: / | Q87: /
A88: 923016 | B88: 'HYGOV' | C88: 1 | D88: 0.03 | E88: 0.18 | F88: 6.64 | G88: 0.05 | H88: 0.5 | I88: 0.15 | J88: 1 | K88: 0 | L88: 1.66 | M88: 1.41 | N88: 0.499 | O88: 0.06 | P88: / | Q88: /
A89: 923017 | B89: 'HYGOV' | C89: 1 | D89: 0.03 | E89: 0.18 | F89: 6.64 | G89: 0.05 | H89: 0.5 | I89: 0.15 | J89: 1 | K89: 0 | L89: 1.66 | M89: 1.41 | N89: 0.499 | O89: 0.06 | P89: / | Q89: /
A90: 923018 | B90: 'HYGOV' | C90: 1 | D90: 0.03 | E90: 0.18 | F90: 6.64 | G90: 0.05 | H90: 0.5 | I90: 0.15 | J90: 1 | K90: 0 | L90: 1.66 | M90: 1.41 | N90: 0.499 | O90: 0.06 | P90: / | Q90: /
A91: 924001 | B91: 'TGOV1' | C91: 1 | D91: 0.03 | E91: 0.499 | F91: 1 | G91: 0 | H91: 4 | I91: 9 | J91: 0.1 | K91: / | L91: /
A92: 924002 | B92: 'TGOV1' | C92: 1 | D92: 0.03 | E92: 0.499 | F92: 1 | G92: 0 | H92: 4 | I92: 9 | J92: 0.1 | K92: / | L92: /
A93: 924002 | B93: 'TGOV1' | C93: 2 | D93: 0.03 | E93: 0.499 | F93: 1 | G93: 0 | H93: 4 | I93: 9 | J93: 0.1 | K93: / | L93: /
A94: 926011 | B94: 'TGOV1' | C94: 1 | D94: 0.03 | E94: 0.499 | F94: 1 | G94: 0 | H94: 4 | I94: 9 | J94: 0.1 | K94: / | L94: /
...

Sheet PSS0
A1: 113015 | B1: 'PSS2A' | C1: 1 | D1: 1 | E1: 0 | F1: 3 | G1: 0 | H1: 5 | I1: 1 | J1: 2.5 | K1: 2.5 | L1: 0 | M1: 2.5 | N1: 0 | O1: 2.5 | P1: 0.39 | Q1: 1 | R1: 0 | S1: 0.1 | T1: 6.5 | U1: 0.44 | V1: 0.08 | W1: 0.2 | X1: 0.98 | Y1: 0.1 | Z1: -0.1 | AA1: /
A2: 113017 | B2: 'PSS2A' | C2: 1 | D2: 1 | E2: 0 | F2: 3 | G2: 0 | H2: 5 | I2: 1 | J2: 2.5 | K2: 2.5 | L2: 0 | M2: 2.5 | N2: 0 | O2: 2.5 | P2: 0.39 | Q2: 1 | R2: 0 | S2: 0.1 | T2: 6.5 | U2: 0.44 | V2: 0.08 | W2: 0.2 | X2: 0.98 | Y2: 0.1 | Z2: -0.1 | AA2: /
A3: 126047 | B3: 'PSS2A' | C3: 1 | D3: 1 | E3: 0 | F3: 3 | G3: 0 | H3: 5 | I3: 1 | J3: 2.5 | K3: 2.5 | L3: 0 | M3: 2.5 | N3: 0 | O3: 2.5 | P3: 0.39 | Q3: 1 | R3: 0 | S3: 0.1 | T3: 6.5 | U3: 0.44 | V3: 0.08 | W3: 0.2 | X3: 0.98 | Y3: 0.1 | Z3: -0.1 | AA3: /
A4: 213019 | B4: 'PSS2A' | C4: 1 | D4: 1 | E4: 0 | F4: 3 | G4: 0 | H4: 5 | I4: 1 | J4: 2.5 | K4: 2.5 | L4: 0 | M4: 2.5 | N4: 0 | O4: 2.5 | P4: 0.39 | Q4: 1 | R4: 0 | S4: 0.1 | T4: 6.5 | U4: 0.44 | V4: 0.08 | W4: 0.2 | X4: 0.98 | Y4: 0.1 | Z4: -0.1 | AA4: /
A5: 213021 | B5: 'PSS2A' | C5: 1 | D5: 1 | E5: 0 | F5: 3 | G5: 0 | H5: 5 | I5: 1 | J5: 2.5 | K5: 2.5 | L5: 0 | M5: 2.5 | N5: 0 | O5: 2.5 | P5: 0.39 | Q5: 1 | R5: 0 | S5: 0.1 | T5: 6.5 | U5: 0.44 | V5: 0.08 | W5: 0.2 | X5: 0.98 | Y5: 0.1 | Z5: -0.1 | AA5: /
A6: 213031 | B6: 'PSS2A' | C6: 1 | D6: 1 | E6: 0 | F6: 3 | G6: 0 | H6: 5 | I6: 1 | J6: 2.5 | K6: 2.5 | L6: 0 | M6: 2.5 | N6: 0 | O6: 2.5 | P6: 0.39 | Q6: 1 | R6: 0 | S6: 0.1 | T6: 6.5 | U6: 0.44 | V6: 0.08 | W6: 0.2 | X6: 0.98 | Y6: 0.1 | Z6: -0.1 | AA6: /
A7: 213041 | B7: 'PSS2A' | C7: 1 | D7: 1 | E7: 0 | F7: 3 | G7: 0 | H7: 5 | I7: 1 | J7: 2.5 | K7: 2.5 | L7: 0 | M7: 2.5 | N7: 0 | O7: 2.5 | P7: 0.39 | Q7: 1 | R7: 0 | S7: 0.1 | T7: 6.5 | U7: 0.44 | V7: 0.08 | W7: 0.2 | X7: 0.98 | Y7: 0.1 | Z7: -0.1 | AA7: /
A8: 213051 | B8: 'PSS2A' | C8: 1 | D8: 1 | E8: 0 | F8: 3 | G8: 0 | H8: 5 | I8: 1 | J8: 2.5 | K8: 2.5 | L8: 0 | M8: 2.5 | N8: 0 | O8: 2.5 | P8: 0.39 | Q8: 1 | R8: 0 | S8: 0.1 | T8: 6.5 | U8: 0.44 | V8: 0.08 | W8: 0.2 | X8: 0.98 | Y8: 0.1 | Z8: -0.1 | AA8: /
A9: 216011 | B9: 'PSS2A' | C9: 1 | D9: 1 | E9: 0 | F9: 3 | G9: 0 | H9: 5 | I9: 1 | J9: 2.5 | K9: 2.5 | L9: 0 | M9: 2.5 | N9: 0 | O9: 2.5 | P9: 0.39 | Q9: 1 | R9: 0 | S9: 0.1 | T9: 6.5 | U9: 0.44 | V9: 0.08 | W9: 0.2 | X9: 0.98 | Y9: 0.1 | Z9: -0.1 | AA9: /
A10: 821012 | B10: 'PSS2A' | C10: 1 | D10: 1 | E10: 0 | F10: 3 | G10: 0 | H10: 5 | I10: 1 | J10: 2.5 | K10: 2.5 | L10: 0 | M10: 2.5 | N10: 0 | O10: 2.5 | P10: 0.39 | Q10: 1 | R10: 0 | S10: 0.1 | T10: 6.5 | U10: 0.44 | V10: 0.08 | W10: 0.2 | X10: 0.98 | Y10: 0.1 | Z10: -0.1 | AA10: /
A11: 910011 | B11: 'PSS2A' | C11: 1 | D11: 1 | E11: 0 | F11: 3 | G11: 0 | H11: 5 | I11: 1 | J11: 2.5 | K11: 2.5 | L11: 0 | M11: 2.5 | N11: 0 | O11: 2.5 | P11: 0.39 | Q11: 1 | R11: 0 | S11: 0.1 | T11: 6.5 | U11: 0.44 | V11: 0.08 | W11: 0.2 | X11: 0.98 | Y11: 0.1 | Z11: -0.1 | AA11: /
A12: 912011 | B12: 'PSS2A' | C12: 1 | D12: 1 | E12: 0 | F12: 3 | G12: 0 | H12: 5 | I12: 1 | J12: 2.5 | K12: 2.5 | L12: 0 | M12: 2.5 | N12: 0 | O12: 2.5 | P12: 0.39 | Q12: 1 | R12: 0 | S12: 0.1 | T12: 6.5 | U12: 0.44 | V12: 0.08 | W12: 0.2 | X12: 0.98 | Y12: 0.1 | Z12: -0.1 | AA12: /
... A682: 918010 | B682: 'PSS2A' | C682: 1 | D682: 1 | E682: 0 | F682: 3 | G682: 0 | H682: 5 | I682: 1 | J682: 2.5 | K682: 2.5 | L682: 0 | M682: 2.5 | N682: 0 | O682: 2.5 | P682: 0.39 | Q682: 1 | R682: 0 | S682: 0.1 | T682: 6.5 | U682: 0.44 | V682: 0.08 | W682: 0.2 | X682: 0.98 | Y682: 0.1 | Z682: -0.1 | AA682: /

Sheet PSSE
A1: IBUS | B1: NAME | C1: ID MACHINE | D1: VOLTAGE | E1: PMAX | F1: TYPE PLANT | G1: TYPE DYR | H1: INDEX | I1: COUNT
D2: (kV) | E2: (MW)
A3: 113015 | B3: HAKHAU1 | C3: 1 | D3: 110 | E3: 150 | F3: TQ | G3: 1 | H3: ="GEN"&D3&E3&F3&G3 -> GEN110150TQ1 | I3: =COUNTIF(Data!$G$3:$BA$2935,$H3) -> 1
A4: 113017 | B4: MAOMAOTIAO1 | C4: 1 | D4: 110 | E4: 150 | F4: TQ | G4: 1 | H4: ="GEN"&D4&E4&F4&G4 -> GEN110150TQ1 | I4: =COUNTIF(Data!$G$3:$BA$2935,$H4) -> 1
A5: 126047 | B5: THAMCAU1 | C5: 1 | D5: 110 | E5: 150 | F5: TQ | G5: 1 | H5: ="GEN"&D5&E5&F5&G5 -> GEN110150TQ1 | I5: =COUNTIF(Data!$G$3:$BA$2935,$H5) -> 1
A6: 151019 | B6: TD_NHO | C6: 1 | D6: 110 | E6: 10 | F6: TQ | G6: 1 | H6: ="GEN"&D6&E6&F6&G6 -> GEN11010TQ1 | I6: =COUNTIF(Data!$G$3:$BA$2935,$H6) -> 0
A7: 151027 | B7: VANXA | C7: 1 | D7: 110 | E7: 25 | F7: TQ | G7: 1 | H7: ="GEN"&D7&E7&F7&G7 -> GEN11025TQ1 | I7: =COUNTIF(Data!$G$3:$BA$2935,$H7) -> 0
A8: 151028 | B8: DONGLAM | C8: 1 | D8: 110 | E8: 27 | F8: TQ | G8: 1 | H8: ="GEN"&D8&E8&F8&G8 -> GEN11027TQ1 | I8: =COUNTIF(Data!$G$3:$BA$2935,$H8) -> 0
A9: 152027 | B9: TD_TATRACH | C9: 1 | D9: 110 | E9: 13 | F9: TQ | G9: 1 | H9: ="GEN"&D9&E9&F9&G9 -> GEN11013TQ1 | I9: =COUNTIF(Data!$G$3:$BA$2935,$H9) -> 0
A10: 213019 | B10: MAGUAN2 | C10: 1 | D10: 220 | E10: 300 | F10: TQ | G10: 1 | H10: ="GEN"&D10&E10&F10&G10 -> GEN220300TQ1 | I10: =COUNTIF(Data!$G$3:$BA$2935,$H10) -> 1
A11: 216011 | B11: TANKIEU2 | C11: 1 | D11: 220 | E11: 300 | F11: TQ | G11: 1 | H11: ="GEN"&D11&E11&F11&G11 -> GEN220300TQ1 | I11: =COUNTIF(Data!$G$3:$BA$2935,$H11) -> 1
A12: 451011 | B12: TD_QT_S1 | C12: 1 | D12: 13.8 | E12: 25 | F12: TQ | G12: 1 | H12: ="GEN"&D12&E12&F12&G12 -> GEN13.825TQ1 | I12: =COUNTIF(Data!$G$3:$BA$2935,$H12) -> 0
A13: 821012 | B13: SVC_VIETTRI4 | C13: 1 | D13: 23 | E13: 0 | F13: SVC | G13: 1 | H13: ="GEN"&D13&E13&F13&G13 -> GEN230SVC1 | I13: =COUNTIF(Data!$G$3:$BA$2935,$H13) -> 1
A14: 910011 | B14: BAOLAC_H1 | C14: 1 | D14: 15.8 | E14: 180 | F14: TD | G14: 1 | H14: ="GEN"&D14&E14&F14&G14 -> GEN15.8180TD1 | I14: =COUNTIF(Data!$G$3:$BA$2935,$H14) -> 1
... A597: 991025 | B597: CAMAU_S3 | C597: 1 | D597: 20 | E597: 253 | F597: ND | G597: 1 | H597: ="GEN"&D597&E597&F597&G597 -> GEN20253ND1 | I597: =COUNTIF(Data!$G$3:$BA$2935,$H597) -> 1

Sheet AVR
A2: =PSSE!A3 -> 113015 | B2: =PSSE!B3 -> HAKHAU1 | C2: =PSSE!D3 -> 110 | D2: =PSSE!E3 -> 150 | E2: =PSSE!F3 -> TQ | F2: =PSSE!G3 -> 1 | G2: ="AVR"&C2&D2&E2&F2 -> AVR110150TQ1 | H2: =COUNTIF(Data!$G$3:$BA$2935,AVR!$G2) -> 1 | I2: =IF($H2=0,"",VLOOKUP($G2,Data!$G$3:$BA$2935,2,FALSE)) -> 'ESST4B' | J2: =PSSE!C3 -> 1 | K2: =IF($H2=0,"",VLOOKUP($G2,Data!$G$3:$BA$2935,4,FALSE)) -> 0 | L2: =IF($H2=0,"",VLOOKUP($G2,Data!$G$3:$BA$2935,5,FALSE)) -> 15 | M2: =IF($H2=0,"",VLOOKUP($G2,Data!$G$3:$BA$2935,6,FALSE)) -> 15 | N2: =IF($H2=0,"",VLOOKUP($G2,Data!$G$3:$BA$2935,7,FALSE)) -> 5 | O2: =IF($H2=0,"",VLOOKUP($G2,Data!$G$3:$BA$2935,8,FALSE)) -> -0.87 | P2: =IF($H2=0,"",VLOOKUP($G2,Data!$G$3:$BA$2935,9,FALSE)) -> 0 | Q2: =IF($H2=0,"",VLOOKUP($G2,Data!$G$3:$BA$2935,10,FALSE)) -> 1 | R2: =IF($H2=0,"",VLOOKUP($G2,Data!$G$3:$BA$2935,11,FALSE)) -> 0 | S2: =IF($H2=0,"",VLOOKUP($G2,Data!$G$3:$BA$2935,12,FALSE)) -> 99 | T2: =IF($H2=0,"",VLOOKUP($G2,Data!$G$3:$BA$2935,13,FALSE)) -> -99 | U2: =IF($H2=0,"",VLOOKUP($G2,Data!$G$3:$BA$2935,14,FALSE)) -> 0 | V2: =IF($H2=0,"",VLOOKUP($G2,Data!$G$3:$BA$2935,15,FALSE)) -> 9.3 | W2: =IF($H2=0,"",VLOOKUP($G2,Data!$G$3:$BA$2935,16,FALSE)) -> 0 | X2: =IF($H2=0,"",VLOOKUP($G2,Data!$G$3:$BA$2935,17,FALSE)) -> 11.63 | Y2: =IF($H2=0,"",VLOOKUP($G2,Data!$G$3:$BA$2935,18,FALSE)) -> 0.113 | Z2: =IF($H2=0,"",VLOOKUP($G2,Data!$G$3:$BA$2935,19,FALSE)) -> 0.124 | AA2: =IF($H2=0,"",VLOOKUP($G2,Data!$G$3:$BA$2935,20,FALSE)) -> 0 | AB2: =IF($H2=0,"",VLOOKUP($G2,Data!$G$3:$BA$2935,21,FALSE)) -> / | AC2: =IF($H2=0,"",VLOOKUP($G2,Data!$G$3:$BA$2935,22,FALSE)) -> / | AD2: =IF($H2=0,"",VLOOKUP($G2,Data!$G$3:$BA$2935,23,FALSE)) | AE2: =IF($H2=0,"",VLOOKUP($G2,Data!$G$3:$BA$2935,24,FALSE)) | AF2: =IF($H2=0,"",VLOOKUP($G2,Data!$G$3:$BA$2935,25,FALSE)) | AG2: =IF($H2=0,"",VLOOKUP($G2,Data!$G$3:$BA$2935,26,FALSE)) | AH2: =IF($H2=0,"",VLOOKUP($G2,Data!$G$3:$BA$2935,27,FALSE)) | AI2: =IF($H2=0,"",VLOOKUP($G2,Data!$G$3:$BA$2935,28,FALSE)) | AJ2: =IF($H2=0,"",VLOOKUP($G2,Data!$G$3:$BA$2935,29,FALSE)) | AK2: =IF($H2=0,"",VLOOKUP($G2,Data!$G$3:$BA$2935,30,FALSE)) | AL2: =IF($H2=0,"",VLOOKUP($G2,Data!$G$3:$BA$2935,31,FALSE)) | AM2: =IF($H2=0,"",VLOOKUP($G2,Data!$G$3:$BA$2935,32,FALSE)) | AN2: =IF($H2=0,"",VLOOKUP($G2,Data!$G$3:$BA$2935,33,FALSE)) | AO2: =IF($H2=0,"",VLOOKUP($G2,Data!$G$3:$BA$2935,34,FALSE)) | AP2: =IF($H2=0,"",VLOOKUP($G2,Data!$G$3:$BA$2935,35,FALSE)) | AQ2: =IF($H2=0,"",VLOOKUP($G2,Data!$G$3:$BA$2935,36,FALSE)) | AR2: =IF($H2=0,"",VLOOKUP($G2,Data!$G$3:$BA$2935,37,FALSE)) | AS2: =IF($H2=0,"",VLOOKUP($G2,Data!$G$3:$BA$2935,38,FALSE)) | AT2: =IF($H2=0,"",VLOOKUP($G2,Data!$G$3:$BA$2935,39,FALSE))
A3: =PSSE!A4 -> 113017 | B3: =PSSE!B4 -> MAOMAOTIAO1 | C3: =PSSE!D4 -> 110 | D3: =PSSE!E4 -> 150 | E3: =PSSE!F4 -> TQ | F3: =PSSE!G4 -> 1 | G3: ="AVR"&C3&D3&E3&F3 -> AVR110150TQ1 | H3: =COUNTIF(Data!$G$3:$BA$2935,AVR!$G3) -> 1 | I3: =IF($H3=0,"",VLOOKUP($G3,Data!$G$3:$BA$2935,2,FALSE)) -> 'ESST4B' | J3: =PSSE!C4 -> 1 | K3: =IF($H3=0,"",VLOOKUP($G3,Data!$G$3:$BA$2935,4,FALSE)) -> 0 | L3: =IF($H3=0,"",VLOOKUP($G3,Data!$G$3:$BA$2935,5,FALSE)) -> 15 | M3: =IF($H3=0,"",VLOOKUP($G3,Data!$G$3:$BA$2935,6,FALSE)) -> 15 | N3: =IF($H3=0,"",VLOOKUP($G3,Data!$G$3:$BA$2935,7,FALSE)) -> 5 | O3: =IF($H3=0,"",VLOOKUP($G3,Data!$G$3:$BA$2935,8,FALSE)) -> -0.87 | P3: =IF($H3=0,"",VLOOKUP($G3,Data!$G$3:$BA$2935,9,FALSE)) -> 0 | Q3: =IF($H3=0,"",VLOOKUP($G3,Data!$G$3:$BA$2935,10,FALSE)) -> 1 | R3: =IF($H3=0,"",VLOOKUP($G3,Data!$G$3:$BA$2935,11,FALSE)) -> 0 | S3: =IF($H3=0,"",VLOOKUP($G3,Data!$G$3:$BA$2935,12,FALSE)) -> 99 | T3: =IF($H3=0,"",VLOOKUP($G3,Data!$G$3:$BA$2935,13,FALSE)) -> -99 | U3: =IF($H3=0,"",VLOOKUP($G3,Data!$G$3:$BA$2935,14,FALSE)) -> 0 | V3: =IF($H3=0,"",VLOOKUP($G3,Data!$G$3:$BA$2935,15,FALSE)) -> 9.3 | W3: =IF($H3=0,"",VLOOKUP($G3,Data!$G$3:$BA$2935,16,FALSE)) -> 0 | X3: =IF($H3=0,"",VLOOKUP($G3,Data!$G$3:$BA$2935,17,FALSE)) -> 11.63 | Y3: =IF($H3=0,"",VLOOKUP($G3,Data!$G$3:$BA$2935,18,FALSE)) -> 0.113 | Z3: =IF($H3=0,"",VLOOKUP($G3,Data!$G$3:$BA$2935,19,FALSE)) -> 0.124 | AA3: =IF($H3=0,"",VLOOKUP($G3,Data!$G$3:$BA$2935,20,FALSE)) -> 0 | AB3: =IF($H3=0,"",VLOOKUP($G3,Data!$G$3:$BA$2935,21,FALSE)) -> / | AC3: =IF($H3=0,"",VLOOKUP($G3,Data!$G$3:$BA$2935,22,FALSE)) -> / | AD3: =IF($H3=0,"",VLOOKUP($G3,Data!$G$3:$BA$2935,23,FALSE)) | AE3: =IF($H3=0,"",VLOOKUP($G3,Data!$G$3:$BA$2935,24,FALSE)) | AF3: =IF($H3=0,"",VLOOKUP($G3,Data!$G$3:$BA$2935,25,FALSE)) | AG3: =IF($H3=0,"",VLOOKUP($G3,Data!$G$3:$BA$2935,26,FALSE)) | AH3: =IF($H3=0,"",VLOOKUP($G3,Data!$G$3:$BA$2935,27,FALSE)) | AI3: =IF($H3=0,"",VLOOKUP($G3,Data!$G$3:$BA$2935,28,FALSE)) | AJ3: =IF($H3=0,"",VLOOKUP($G3,Data!$G$3:$BA$2935,29,FALSE)) | AK3: =IF($H3=0,"",VLOOKUP($G3,Data!$G$3:$BA$2935,30,FALSE)) | AL3: =IF($H3=0,"",VLOOKUP($G3,Data!$G$3:$BA$2935,31,FALSE)) | AM3: =IF($H3=0,"",VLOOKUP($G3,Data!$G$3:$BA$2935,32,FALSE)) | AN3: =IF($H3=0,"",VLOOKUP($G3,Data!$G$3:$BA$2935,33,FALSE)) | AO3: =IF($H3=0,"",VLOOKUP($G3,Data!$G$3:$BA$2935,34,FALSE)) | AP3: =IF($H3=0,"",VLOOKUP($G3,Data!$G$3:$BA$2935,35,FALSE)) | AQ3: =IF($H3=0,"",VLOOKUP($G3,Data!$G$3:$BA$2935,36,FALSE)) | AR3: =IF($H3=0,"",VLOOKUP($G3,Data!$G$3:$BA$2935,37,FALSE)) | AS3: =IF($H3=0,"",VLOOKUP($G3,Data!$G$3:$BA$2935,38,FALSE)) | AT3: =IF($H3=0,"",VLOOKUP($G3,Data!$G$3:$BA$2935,39,FALSE))
A4: =PSSE!A11 -> 216011 | B4: =PSSE!B11 -> TANKIEU2 | C4: =PSSE!D11 -> 220 | D4: =PSSE!E11 -> 300 | E4: =PSSE!F11 -> TQ | F4: =PSSE!G11 -> 1 | G4: ="AVR"&C4&D4&E4&F4 -> AVR220300TQ1 | H4: =COUNTIF(Data!$G$3:$BA$2935,AVR!$G4) -> 1 | I4: =IF($H4=0,"",VLOOKUP($G4,Data!$G$3:$BA$2935,2,FALSE)) -> 'ESST4B' | J4: =PSSE!C11 -> 1 | K4: =IF($H4=0,"",VLOOKUP($G4,Data!$G$3:$BA$2935,4,FALSE)) -> 0 | L4: =IF($H4=0,"",VLOOKUP($G4,Data!$G$3:$BA$2935,5,FALSE)) -> 15 | M4: =IF($H4=0,"",VLOOKUP($G4,Data!$G$3:$BA$2935,6,FALSE)) -> 15 | N4: =IF($H4=0,"",VLOOKUP($G4,Data!$G$3:$BA$2935,7,FALSE)) -> 5 | O4: =IF($H4=0,"",VLOOKUP($G4,Data!$G$3:$BA$2935,8,FALSE)) -> -0.87 | P4: =IF($H4=0,"",VLOOKUP($G4,Data!$G$3:$BA$2935,9,FALSE)) -> 0 | Q4: =IF($H4=0,"",VLOOKUP($G4,Data!$G$3:$BA$2935,10,FALSE)) -> 1 | R4: =IF($H4=0,"",VLOOKUP($G4,Data!$G$3:$BA$2935,11,FALSE)) -> 0 | S4: =IF($H4=0,"",VLOOKUP($G4,Data!$G$3:$BA$2935,12,FALSE)) -> 99 | T4: =IF($H4=0,"",VLOOKUP($G4,Data!$G$3:$BA$2935,13,FALSE)) -> -99 | U4: =IF($H4=0,"",VLOOKUP($G4,Data!$G$3:$BA$2935,14,FALSE)) -> 0 | V4: =IF($H4=0,"",VLOOKUP($G4,Data!$G$3:$BA$2935,15,FALSE)) -> 9.3 | W4: =IF($H4=0,"",VLOOKUP($G4,Data!$G$3:$BA$2935,16,FALSE)) -> 0 | X4: =IF($H4=0,"",VLOOKUP($G4,Data!$G$3:$BA$2935,17,FALSE)) -> 11.63 | Y4: =IF($H4=0,"",VLOOKUP($G4,Data!$G$3:$BA$2935,18,FALSE)) -> 0.113 | Z4: =IF($H4=0,"",VLOOKUP($G4,Data!$G$3:$BA$2935,19,FALSE)) -> 0.124 | AA4: =IF($H4=0,"",VLOOKUP($G4,Data!$G$3:$BA$2935,20,FALSE)) -> 0 | AB4: =IF($H4=0,"",VLOOKUP($G4,Data!$G$3:$BA$2935,21,FALSE)) -> / | AC4: =IF($H4=0,"",VLOOKUP($G4,Data!$G$3:$BA$2935,22,FALSE)) -> / | AD4: =IF($H4=0,"",VLOOKUP($G4,Data!$G$3:$BA$2935,23,FALSE)) | AE4: =IF($H4=0,"",VLOOKUP($G4,Data!$G$3:$BA$2935,24,FALSE)) | AF4: =IF($H4=0,"",VLOOKUP($G4,Data!$G$3:$BA$2935,25,FALSE)) | AG4: =IF($H4=0,"",VLOOKUP($G4,Data!$G$3:$BA$2935,26,FALSE)) | AH4: =IF($H4=0,"",VLOOKUP($G4,Data!$G$3:$BA$2935,27,FALSE)) | AI4: =IF($H4=0,"",VLOOKUP($G4,Data!$G$3:$BA$2935,28,FALSE)) | AJ4: =IF($H4=0,"",VLOOKUP($G4,Data!$G$3:$BA$2935,29,FALSE)) | AK4: =IF($H4=0,"",VLOOKUP($G4,Data!$G$3:$BA$2935,30,FALSE)) | AL4: =IF($H4=0,"",VLOOKUP($G4,Data!$G$3:$BA$2935,31,FALSE)) | AM4: =IF($H4=0,"",VLOOKUP($G4,Data!$G$3:$BA$2935,32,FALSE)) | AN4: =IF($H4=0,"",VLOOKUP($G4,Data!$G$3:$BA$2935,33,FALSE)) | AO4: =IF($H4=0,"",VLOOKUP($G4,Data!$G$3:$BA$2935,34,FALSE)) | AP4: =IF($H4=0,"",VLOOKUP($G4,Data!$G$3:$BA$2935,35,FALSE)) | AQ4: =IF($H4=0,"",VLOOKUP($G4,Data!$G$3:$BA$2935,36,FALSE)) | AR4: =IF($H4=0,"",VLOOKUP($G4,Data!$G$3:$BA$2935,37,FALSE)) | AS4: =IF($H4=0,"",VLOOKUP($G4,Data!$G$3:$BA$2935,38,FALSE)) | AT4: =IF($H4=0,"",VLOOKUP($G4,Data!$G$3:$BA$2935,39,FALSE))
A5: =PSSE!A14 -> 910011 | B5: =PSSE!B14 -> BAOLAC_H1 | C5: =PSSE!D14 -> 15.8 | D5: =PSSE!E14 -> 180 | E5: =PSSE!F14 -> TD | F5: =PSSE!G14 -> 1 | G5: ="AVR"&C5&D5&E5&F5 -> AVR15.8180TD1 | H5: =COUNTIF(Data!$G$3:$BA$2935,AVR!$G5) -> 1 | I5: =IF($H5=0,"",VLOOKUP($G5,Data!$G$3:$BA$2935,2,FALSE)) -> 'ESST4B' | J5: =PSSE!C14 -> 1 | K5: =IF($H5=0,"",VLOOKUP($G5,Data!$G$3:$BA$2935,4,FALSE)) -> 0 | L5: =IF($H5=0,"",VLOOKUP($G5,Data!$G$3:$BA$2935,5,FALSE)) -> 10.75 | M5: =IF($H5=0,"",VLOOKUP($G5,Data!$G$3:$BA$2935,6,FALSE)) -> 10.75 | N5: =IF($H5=0,"",VLOOKUP($G5,Data!$G$3:$BA$2935,7,FALSE)) -> 5 | O5: =IF($H5=0,"",VLOOKUP($G5,Data!$G$3:$BA$2935,8,FALSE)) -> -0.87 | P5: =IF($H5=0,"",VLOOKUP($G5,Data!$G$3:$BA$2935,9,FALSE)) -> 0 | Q5: =IF($H5=0,"",VLOOKUP($G5,Data!$G$3:$BA$2935,10,FALSE)) -> 1 | R5: =IF($H5=0,"",VLOOKUP($G5,Data!$G$3:$BA$2935,11,FALSE)) -> 0 | S5: =IF($H5=0,"",VLOOKUP($G5,Data!$G$3:$BA$2935,12,FALSE)) -> 99 | T5: =IF($H5=0,"",VLOOKUP($G5,Data!$G$3:$BA$2935,13,FALSE)) -> -99 | U5: =IF($H5=0,"",VLOOKUP($G5,Data!$G$3:$BA$2935,14,FALSE)) -> 0 | V5: =IF($H5=0,"",VLOOKUP($G5,Data!$G$3:$BA$2935,15,FALSE)) -> 9.3 | W5: =IF($H5=0,"",VLOOKUP($G5,Data!$G$3:$BA$2935,16,FALSE)) -> 0 | X5: =IF($H5=0,"",VLOOKUP($G5,Data!$G$3:$BA$2935,17,FALSE)) -> 11.63 | Y5: =IF($H5=0,"",VLOOKUP($G5,Data!$G$3:$BA$2935,18,FALSE)) -> 0.113 | Z5: =IF($H5=0,"",VLOOKUP($G5,Data!$G$3:$BA$2935,19,FALSE)) -> 0.124 | AA5: =IF($H5=0,"",VLOOKUP($G5,Data!$G$3:$BA$2935,20,FALSE)) -> 0 | AB5: =IF($H5=0,"",VLOOKUP($G5,Data!$G$3:$BA$2935,21,FALSE)) -> / | AC5: =IF($H5=0,"",VLOOKUP($G5,Data!$G$3:$BA$2935,22,FALSE)) -> / | AD5: =IF($H5=0,"",VLOOKUP($G5,Data!$G$3:$BA$2935,23,FALSE)) | AE5: =IF($H5=0,"",VLOOKUP($G5,Data!$G$3:$BA$2935,24,FALSE)) | AF5: =IF($H5=0,"",VLOOKUP($G5,Data!$G$3:$BA$2935,25,FALSE)) | AG5: =IF($H5=0,"",VLOOKUP($G5,Data!$G$3:$BA$2935,26,FALSE)) | AH5: =IF($H5=0,"",VLOOKUP($G5,Data!$G$3:$BA$2935,27,FALSE)) | AI5: =IF($H5=0,"",VLOOKUP($G5,Data!$G$3:$BA$2935,28,FALSE)) | AJ5: =IF($H5=0,"",VLOOKUP($G5,Data!$G$3:$BA$2935,29,FALSE)) | AK5: =IF($H5=0,"",VLOOKUP($G5,Data!$G$3:$BA$2935,30,FALSE)) | AL5: =IF($H5=0,"",VLOOKUP($G5,Data!$G$3:$BA$2935,31,FALSE)) | AM5: =IF($H5=0,"",VLOOKUP($G5,Data!$G$3:$BA$2935,32,FALSE)) | AN5: =IF($H5=0,"",VLOOKUP($G5,Data!$G$3:$BA$2935,33,FALSE)) | AO5: =IF($H5=0,"",VLOOKUP($G5,Data!$G$3:$BA$2935,34,FALSE)) | AP5: =IF($H5=0,"",VLOOKUP($G5,Data!$G$3:$BA$2935,35,FALSE)) | AQ5: =IF($H5=0,"",VLOOKUP($G5,Data!$G$3:$BA$2935,36,FALSE)) | AR5: =IF($H5=0,"",VLOOKUP($G5,Data!$G$3:$BA$2935,37,FALSE)) | AS5: =IF($H5=0,"",VLOOKUP($G5,Data!$G$3:$BA$2935,38,FALSE)) | AT5: =IF($H5=0,"",VLOOKUP($G5,Data!$G$3:$BA$2935,39,FALSE))
A6: =PSSE!A15 -> 910021 | B6: =PSSE!B15 -> BANRA1_S1 | C6: =PSSE!D15 -> 6.3 | D6: =PSSE!E15 -> 55 | E6: =PSSE!F15 -> ND | F6: =PSSE!G15 -> 1 | G6: ="AVR"&C6&D6&E6&F6 -> AVR6.355ND1 | H6: =COUNTIF(Data!$G$3:$BA$2935,AVR!$G6) -> 1 | I6: =IF($H6=0,"",VLOOKUP($G6,Data!$G$3:$BA$2935,2,FALSE)) -> 'ESST4B' | J6: =PSSE!C15 -> 1 | K6: =IF($H6=0,"",VLOOKUP($G6,Data!$G$3:$BA$2935,4,FALSE)) -> 0 | L6: =IF($H6=0,"",VLOOKUP($G6,Data!$G$3:$BA$2935,5,FALSE)) -> 15 | M6: =IF($H6=0,"",VLOOKUP($G6,Data!$G$3:$BA$2935,6,FALSE)) -> 15 | N6: =IF($H6=0,"",VLOOKUP($G6,Data!$G$3:$BA$2935,7,FALSE)) -> 5 | O6: =IF($H6=0,"",VLOOKUP($G6,Data!$G$3:$BA$2935,8,FALSE)) -> -0.87 | P6: =IF($H6=0,"",VLOOKUP($G6,Data!$G$3:$BA$2935,9,FALSE)) -> 0 | Q6: =IF($H6=0,"",VLOOKUP($G6,Data!$G$3:$BA$2935,10,FALSE)) -> 1 | R6: =IF($H6=0,"",VLOOKUP($G6,Data!$G$3:$BA$2935,11,FALSE)) -> 0 | S6: =IF($H6=0,"",VLOOKUP($G6,Data!$G$3:$BA$2935,12,FALSE)) -> 99 | T6: =IF($H6=0,"",VLOOKUP($G6,Data!$G$3:$BA$2935,13,FALSE)) -> -99 | U6: =IF($H6=0,"",VLOOKUP($G6,Data!$G$3:$BA$2935,14,FALSE)) -> 0 | V6: =IF($H6=0,"",VLOOKUP($G6,Data!$G$3:$BA$2935,15,FALSE)) -> 9.3 | W6: =IF($H6=0,"",VLOOKUP($G6,Data!$G$3:$BA$2935,16,FALSE)) -> 0 | X6: =IF($H6=0,"",VLOOKUP($G6,Data!$G$3:$BA$2935,17,FALSE)) -> 11.63 | Y6: =IF($H6=0,"",VLOOKUP($G6,Data!$G$3:$BA$2935,18,FALSE)) -> 0.113 | Z6: =IF($H6=0,"",VLOOKUP($G6,Data!$G$3:$BA$2935,19,FALSE)) -> 0.124 | AA6: =IF($H6=0,"",VLOOKUP($G6,Data!$G$3:$BA$2935,20,FALSE)) -> 0 | AB6: =IF($H6=0,"",VLOOKUP($G6,Data!$G$3:$BA$2935,21,FALSE)) -> / | AC6: =IF($H6=0,"",VLOOKUP($G6,Data!$G$3:$BA$2935,22,FALSE)) -> / | AD6: =IF($H6=0,"",VLOOKUP($G6,Data!$G$3:$BA$2935,23,FALSE)) | AE6: =IF($H6=0,"",VLOOKUP($G6,Data!$G$3:$BA$2935,24,FALSE)) | AF6: =IF($H6=0,"",VLOOKUP($G6,Data!$G$3:$BA$2935,25,FALSE)) | AG6: =IF($H6=0,"",VLOOKUP($G6,Data!$G$3:$BA$2935,26,FALSE)) | AH6: =IF($H6=0,"",VLOOKUP($G6,Data!$G$3:$BA$2935,27,FALSE)) | AI6: =IF($H6=0,"",VLOOKUP($G6,Data!$G$3:$BA$2935,28,FALSE)) | AJ6: =IF($H6=0,"",VLOOKUP($G6,Data!$G$3:$BA$2935,29,FALSE)) | AK6: =IF($H6=0,"",VLOOKUP($G6,Data!$G$3:$BA$2935,30,FALSE)) | AL6: =IF($H6=0,"",VLOOKUP($G6,Data!$G$3:$BA$2935,31,FALSE)) | AM6: =IF($H6=0,"",VLOOKUP($G6,Data!$G$3:$BA$2935,32,FALSE)) | AN6: =IF($H6=0,"",VLOOKUP($G6,Data!$G$3:$BA$2935,33,FALSE)) | AO6: =IF($H6=0,"",VLOOKUP($G6,Data!$G$3:$BA$2935,34,FALSE)) | AP6: =IF($H6=0,"",VLOOKUP($G6,Data!$G$3:$BA$2935,35,FALSE)) | AQ6: =IF($H6=0,"",VLOOKUP($G6,Data!$G$3:$BA$2935,36,FALSE)) | AR6: =IF($H6=0,"",VLOOKUP($G6,Data!$G$3:$BA$2935,37,FALSE)) | AS6: =IF($H6=0,"",VLOOKUP($G6,Data!$G$3:$BA$2935,38,FALSE)) | AT6: =IF($H6=0,"",VLOOKUP($G6,Data!$G$3:$BA$2935,39,FALSE))
A7: =PSSE!A16 -> 912011 | B7: =PSSE!B16 -> NADUONG1_S1 | C7: =PSSE!D16 -> 6.3 | D7: =PSSE!E16 -> 55 | E7: =PSSE!F16 -> ND | F7: =PSSE!G16 -> 1 | G7: ="AVR"&C7&D7&E7&F7 -> AVR6.355ND1 | H7: =COUNTIF(Data!$G$3:$BA$2935,AVR!$G7) -> 1 | I7: =IF($H7=0,"",VLOOKUP($G7,Data!$G$3:$BA$2935,2,FALSE)) -> 'ESST4B' | J7: =PSSE!C16 -> 1 | K7: =IF($H7=0,"",VLOOKUP($G7,Data!$G$3:$BA$2935,4,FALSE)) -> 0 | L7: =IF($H7=0,"",VLOOKUP($G7,Data!$G$3:$BA$2935,5,FALSE)) -> 15 | M7: =IF($H7=0,"",VLOOKUP($G7,Data!$G$3:$BA$2935,6,FALSE)) -> 15 | N7: =IF($H7=0,"",VLOOKUP($G7,Data!$G$3:$BA$2935,7,FALSE)) -> 5 | O7: =IF($H7=0,"",VLOOKUP($G7,Data!$G$3:$BA$2935,8,FALSE)) -> -0.87 | P7: =IF($H7=0,"",VLOOKUP($G7,Data!$G$3:$BA$2935,9,FALSE)) -> 0 | Q7: =IF($H7=0,"",VLOOKUP($G7,Data!$G$3:$BA$2935,10,FALSE)) -> 1 | R7: =IF($H7=0,"",VLOOKUP($G7,Data!$G$3:$BA$2935,11,FALSE)) -> 0 | S7: =IF($H7=0,"",VLOOKUP($G7,Data!$G$3:$BA$2935,12,FALSE)) -> 99 | T7: =IF($H7=0,"",VLOOKUP($G7,Data!$G$3:$BA$2935,13,FALSE)) -> -99 | U7: =IF($H7=0,"",VLOOKUP($G7,Data!$G$3:$BA$2935,14,FALSE)) -> 0 | V7: =IF($H7=0,"",VLOOKUP($G7,Data!$G$3:$BA$2935,15,FALSE)) -> 9.3 | W7: =IF($H7=0,"",VLOOKUP($G7,Data!$G$3:$BA$2935,16,FALSE)) -> 0 | X7: =IF($H7=0,"",VLOOKUP($G7,Data!$G$3:$BA$2935,17,FALSE)) -> 11.63 | Y7: =IF($H7=0,"",VLOOKUP($G7,Data!$G$3:$BA$2935,18,FALSE)) -> 0.113 | Z7: =IF($H7=0,"",VLOOKUP($G7,Data!$G$3:$BA$2935,19,FALSE)) -> 0.124 | AA7: =IF($H7=0,"",VLOOKUP($G7,Data!$G$3:$BA$2935,20,FALSE)) -> 0 | AB7: =IF($H7=0,"",VLOOKUP($G7,Data!$G$3:$BA$2935,21,FALSE)) -> / | AC7: =IF($H7=0,"",VLOOKUP($G7,Data!$G$3:$BA$2935,22,FALSE)) -> / | AD7: =IF($H7=0,"",VLOOKUP($G7,Data!$G$3:$BA$2935,23,FALSE)) | AE7: =IF($H7=0,"",VLOOKUP($G7,Data!$G$3:$BA$2935,24,FALSE)) | AF7: =IF($H7=0,"",VLOOKUP($G7,Data!$G$3:$BA$2935,25,FALSE)) | AG7: =IF($H7=0,"",VLOOKUP($G7,Data!$G$3:$BA$2935,26,FALSE)) | AH7: =IF($H7=0,"",VLOOKUP($G7,Data!$G$3:$BA$2935,27,FALSE)) | AI7: =IF($H7=0,"",VLOOKUP($G7,Data!$G$3:$BA$2935,28,FALSE)) | AJ7: =IF($H7=0,"",VLOOKUP($G7,Data!$G$3:$BA$2935,29,FALSE)) | AK7: =IF($H7=0,"",VLOOKUP($G7,Data!$G$3:$BA$2935,30,FALSE)) | AL7: =IF($H7=0,"",VLOOKUP($G7,Data!$G$3:$BA$2935,31,FALSE)) | AM7: =IF($H7=0,"",VLOOKUP($G7,Data!$G$3:$BA$2935,32,FALSE)) | AN7: =IF($H7=0,"",VLOOKUP($G7,Data!$G$3:$BA$2935,33,FALSE)) | AO7: =IF($H7=0,"",VLOOKUP($G7,Data!$G$3:$BA$2935,34,FALSE)) | AP7: =IF($H7=0,"",VLOOKUP($G7,Data!$G$3:$BA$2935,35,FALSE)) | AQ7: =IF($H7=0,"",VLOOKUP($G7,Data!$G$3:$BA$2935,36,FALSE)) | AR7: =IF($H7=0,"",VLOOKUP($G7,Data!$G$3:$BA$2935,37,FALSE)) | AS7: =IF($H7=0,"",VLOOKUP($G7,Data!$G$3:$BA$2935,38,FALSE)) | AT7: =IF($H7=0,"",VLOOKUP($G7,Data!$G$3:$BA$2935,39,FALSE))
A8: =PSSE!A17 -> 912012 | B8: =PSSE!B17 -> NADUONG1_S2 | C8: =PSSE!D17 -> 6.3 | D8: =PSSE!E17 -> 55 | E8: =PSSE!F17 -> ND | F8: =PSSE!G17 -> 1 | G8: ="AVR"&C8&D8&E8&F8 -> AVR6.355ND1 | H8: =COUNTIF(Data!$G$3:$BA$2935,AVR!$G8) -> 1 | I8: =IF($H8=0,"",VLOOKUP($G8,Data!$G$3:$BA$2935,2,FALSE)) -> 'ESST4B' | J8: =PSSE!C17 -> 1 | K8: =IF($H8=0,"",VLOOKUP($G8,Data!$G$3:$BA$2935,4,FALSE)) -> 0 | L8: =IF($H8=0,"",VLOOKUP($G8,Data!$G$3:$BA$2935,5,FALSE)) -> 15 | M8: =IF($H8=0,"",VLOOKUP($G8,Data!$G$3:$BA$2935,6,FALSE)) -> 15 | N8: =IF($H8=0,"",VLOOKUP($G8,Data!$G$3:$BA$2935,7,FALSE)) -> 5 | O8: =IF($H8=0,"",VLOOKUP($G8,Data!$G$3:$BA$2935,8,FALSE)) -> -0.87 | P8: =IF($H8=0,"",VLOOKUP($G8,Data!$G$3:$BA$2935,9,FALSE)) -> 0 | Q8: =IF($H8=0,"",VLOOKUP($G8,Data!$G$3:$BA$2935,10,FALSE)) -> 1 | R8: =IF($H8=0,"",VLOOKUP($G8,Data!$G$3:$BA$2935,11,FALSE)) -> 0 | S8: =IF($H8=0,"",VLOOKUP($G8,Data!$G$3:$BA$2935,12,FALSE)) -> 99 | T8: =IF($H8=0,"",VLOOKUP($G8,Data!$G$3:$BA$2935,13,FALSE)) -> -99 | U8: =IF($H8=0,"",VLOOKUP($G8,Data!$G$3:$BA$2935,14,FALSE)) -> 0 | V8: =IF($H8=0,"",VLOOKUP($G8,Data!$G$3:$BA$2935,15,FALSE)) -> 9.3 | W8: =IF($H8=0,"",VLOOKUP($G8,Data!$G$3:$BA$2935,16,FALSE)) -> 0 | X8: =IF($H8=0,"",VLOOKUP($G8,Data!$G$3:$BA$2935,17,FALSE)) -> 11.63 | Y8: =IF($H8=0,"",VLOOKUP($G8,Data!$G$3:$BA$2935,18,FALSE)) -> 0.113 | Z8: =IF($H8=0,"",VLOOKUP($G8,Data!$G$3:$BA$2935,19,FALSE)) -> 0.124 | AA8: =IF($H8=0,"",VLOOKUP($G8,Data!$G$3:$BA$2935,20,FALSE)) -> 0 | AB8: =IF($H8=0,"",VLOOKUP($G8,Data!$G$3:$BA$2935,21,FALSE)) -> / | AC8: =IF($H8=0,"",VLOOKUP($G8,Data!$G$3:$BA$2935,22,FALSE)) -> / | AD8: =IF($H8=0,"",VLOOKUP($G8,Data!$G$3:$BA$2935,23,FALSE)) | AE8: =IF($H8=0,"",VLOOKUP($G8,Data!$G$3:$BA$2935,24,FALSE)) | AF8: =IF($H8=0,"",VLOOKUP($G8,Data!$G$3:$BA$2935,25,FALSE)) | AG8: =IF($H8=0,"",VLOOKUP($G8,Data!$G$3:$BA$2935,26,FALSE)) | AH8: =IF($H8=0,"",VLOOKUP($G8,Data!$G$3:$BA$2935,27,FALSE)) | AI8: =IF($H8=0,"",VLOOKUP($G8,Data!$G$3:$BA$2935,28,FALSE)) | AJ8: =IF($H8=0,"",VLOOKUP($G8,Data!$G$3:$BA$2935,29,FALSE)) | AK8: =IF($H8=0,"",VLOOKUP($G8,Data!$G$3:$BA$2935,30,FALSE)) | AL8: =IF($H8=0,"",VLOOKUP($G8,Data!$G$3:$BA$2935,31,FALSE)) | AM8: =IF($H8=0,"",VLOOKUP($G8,Data!$G$3:$BA$2935,32,FALSE)) | AN8: =IF($H8=0,"",VLOOKUP($G8,Data!$G$3:$BA$2935,33,FALSE)) | AO8: =IF($H8=0,"",VLOOKUP($G8,Data!$G$3:$BA$2935,34,FALSE)) | AP8: =IF($H8=0,"",VLOOKUP($G8,Data!$G$3:$BA$2935,35,FALSE)) | AQ8: =IF($H8=0,"",VLOOKUP($G8,Data!$G$3:$BA$2935,36,FALSE)) | AR8: =IF($H8=0,"",VLOOKUP($G8,Data!$G$3:$BA$2935,37,FALSE)) | AS8: =IF($H8=0,"",VLOOKUP($G8,Data!$G$3:$BA$2935,38,FALSE)) | AT8: =IF($H8=0,"",VLOOKUP($G8,Data!$G$3:$BA$2935,39,FALSE))
A9: =PSSE!A18 -> 912013 | B9: =PSSE!B18 -> NADUONG2_S1 | C9: =PSSE!D18 -> 6.3 | D9: =PSSE!E18 -> 55 | E9: =PSSE!F18 -> ND | F9: =PSSE!G18 -> 1 | G9: ="AVR"&C9&D9&E9&F9 -> AVR6.355ND1 | H9: =COUNTIF(Data!$G$3:$BA$2935,AVR!$G9) -> 1 | I9: =IF($H9=0,"",VLOOKUP($G9,Data!$G$3:$BA$2935,2,FALSE)) -> 'ESST4B' | J9: =PSSE!C18 -> 1 | K9: =IF($H9=0,"",VLOOKUP($G9,Data!$G$3:$BA$2935,4,FALSE)) -> 0 | L9: =IF($H9=0,"",VLOOKUP($G9,Data!$G$3:$BA$2935,5,FALSE)) -> 15 | M9: =IF($H9=0,"",VLOOKUP($G9,Data!$G$3:$BA$2935,6,FALSE)) -> 15 | N9: =IF($H9=0,"",VLOOKUP($G9,Data!$G$3:$BA$2935,7,FALSE)) -> 5 | O9: =IF($H9=0,"",VLOOKUP($G9,Data!$G$3:$BA$2935,8,FALSE)) -> -0.87 | P9: =IF($H9=0,"",VLOOKUP($G9,Data!$G$3:$BA$2935,9,FALSE)) -> 0 | Q9: =IF($H9=0,"",VLOOKUP($G9,Data!$G$3:$BA$2935,10,FALSE)) -> 1 | R9: =IF($H9=0,"",VLOOKUP($G9,Data!$G$3:$BA$2935,11,FALSE)) -> 0 | S9: =IF($H9=0,"",VLOOKUP($G9,Data!$G$3:$BA$2935,12,FALSE)) -> 99 | T9: =IF($H9=0,"",VLOOKUP($G9,Data!$G$3:$BA$2935,13,FALSE)) -> -99 | U9: =IF($H9=0,"",VLOOKUP($G9,Data!$G$3:$BA$2935,14,FALSE)) -> 0 | V9: =IF($H9=0,"",VLOOKUP($G9,Data!$G$3:$BA$2935,15,FALSE)) -> 9.3 | W9: =IF($H9=0,"",VLOOKUP($G9,Data!$G$3:$BA$2935,16,FALSE)) -> 0 | X9: =IF($H9=0,"",VLOOKUP($G9,Data!$G$3:$BA$2935,17,FALSE)) -> 11.63 | Y9: =IF($H9=0,"",VLOOKUP($G9,Data!$G$3:$BA$2935,18,FALSE)) -> 0.113 | Z9: =IF($H9=0,"",VLOOKUP($G9,Data!$G$3:$BA$2935,19,FALSE)) -> 0.124 | AA9: =IF($H9=0,"",VLOOKUP($G9,Data!$G$3:$BA$2935,20,FALSE)) -> 0 | AB9: =IF($H9=0,"",VLOOKUP($G9,Data!$G$3:$BA$2935,21,FALSE)) -> / | AC9: =IF($H9=0,"",VLOOKUP($G9,Data!$G$3:$BA$2935,22,FALSE)) -> / | AD9: =IF($H9=0,"",VLOOKUP($G9,Data!$G$3:$BA$2935,23,FALSE)) | AE9: =IF($H9=0,"",VLOOKUP($G9,Data!$G$3:$BA$2935,24,FALSE)) | AF9: =IF($H9=0,"",VLOOKUP($G9,Data!$G$3:$BA$2935,25,FALSE)) | AG9: =IF($H9=0,"",VLOOKUP($G9,Data!$G$3:$BA$2935,26,FALSE)) | AH9: =IF($H9=0,"",VLOOKUP($G9,Data!$G$3:$BA$2935,27,FALSE)) | AI9: =IF($H9=0,"",VLOOKUP($G9,Data!$G$3:$BA$2935,28,FALSE)) | AJ9: =IF($H9=0,"",VLOOKUP($G9,Data!$G$3:$BA$2935,29,FALSE)) | AK9: =IF($H9=0,"",VLOOKUP($G9,Data!$G$3:$BA$2935,30,FALSE)) | AL9: =IF($H9=0,"",VLOOKUP($G9,Data!$G$3:$BA$2935,31,FALSE)) | AM9: =IF($H9=0,"",VLOOKUP($G9,Data!$G$3:$BA$2935,32,FALSE)) | AN9: =IF($H9=0,"",VLOOKUP($G9,Data!$G$3:$BA$2935,33,FALSE)) | AO9: =IF($H9=0,"",VLOOKUP($G9,Data!$G$3:$BA$2935,34,FALSE)) | AP9: =IF($H9=0,"",VLOOKUP($G9,Data!$G$3:$BA$2935,35,FALSE)) | AQ9: =IF($H9=0,"",VLOOKUP($G9,Data!$G$3:$BA$2935,36,FALSE)) | AR9: =IF($H9=0,"",VLOOKUP($G9,Data!$G$3:$BA$2935,37,FALSE)) | AS9: =IF($H9=0,"",VLOOKUP($G9,Data!$G$3:$BA$2935,38,FALSE)) | AT9: =IF($H9=0,"",VLOOKUP($G9,Data!$G$3:$BA$2935,39,FALSE))
A10: =PSSE!A19 -> 912014 | B10: =PSSE!B19 -> NADUONG2_S2 | C10: =PSSE!D19 -> 6.3 | D10: =PSSE!E19 -> 55 | E10: =PSSE!F19 -> ND | F10: =PSSE!G19 -> 1 | G10: ="AVR"&C10&D10&E10&F10 -> AVR6.355ND1 | H10: =COUNTIF(Data!$G$3:$BA$2935,AVR!$G10) -> 1 | I10: =IF($H10=0,"",VLOOKUP($G10,Data!$G$3:$BA$2935,2,FALSE)) -> 'ESST4B' | J10: =PSSE!C19 -> 1 | K10: =IF($H10=0,"",VLOOKUP($G10,Data!$G$3:$BA$2935,4,FALSE)) -> 0 | L10: =IF($H10=0,"",VLOOKUP($G10,Data!$G$3:$BA$2935,5,FALSE)) -> 15 | M10: =IF($H10=0,"",VLOOKUP($G10,Data!$G$3:$BA$2935,6,FALSE)) -> 15 | N10: =IF($H10=0,"",VLOOKUP($G10,Data!$G$3:$BA$2935,7,FALSE)) -> 5 | O10: =IF($H10=0,"",VLOOKUP($G10,Data!$G$3:$BA$2935,8,FALSE)) -> -0.87 | P10: =IF($H10=0,"",VLOOKUP($G10,Data!$G$3:$BA$2935,9,FALSE)) -> 0 | Q10: =IF($H10=0,"",VLOOKUP($G10,Data!$G$3:$BA$2935,10,FALSE)) -> 1 | R10: =IF($H10=0,"",VLOOKUP($G10,Data!$G$3:$BA$2935,11,FALSE)) -> 0 | S10: =IF($H10=0,"",VLOOKUP($G10,Data!$G$3:$BA$2935,12,FALSE)) -> 99 | T10: =IF($H10=0,"",VLOOKUP($G10,Data!$G$3:$BA$2935,13,FALSE)) -> -99 | U10: =IF($H10=0,"",VLOOKUP($G10,Data!$G$3:$BA$2935,14,FALSE)) -> 0 | V10: =IF($H10=0,"",VLOOKUP($G10,Data!$G$3:$BA$2935,15,FALSE)) -> 9.3 | W10: =IF($H10=0,"",VLOOKUP($G10,Data!$G$3:$BA$2935,16,FALSE)) -> 0 | X10: =IF($H10=0,"",VLOOKUP($G10,Data!$G$3:$BA$2935,17,FALSE)) -> 11.63 | Y10: =IF($H10=0,"",VLOOKUP($G10,Data!$G$3:$BA$2935,18,FALSE)) -> 0.113 | Z10: =IF($H10=0,"",VLOOKUP($G10,Data!$G$3:$BA$2935,19,FALSE)) -> 0.124 | AA10: =IF($H10=0,"",VLOOKUP($G10,Data!$G$3:$BA$2935,20,FALSE)) -> 0 | AB10: =IF($H10=0,"",VLOOKUP($G10,Data!$G$3:$BA$2935,21,FALSE)) -> / | AC10: =IF($H10=0,"",VLOOKUP($G10,Data!$G$3:$BA$2935,22,FALSE)) -> / | AD10: =IF($H10=0,"",VLOOKUP($G10,Data!$G$3:$BA$2935,23,FALSE)) | AE10: =IF($H10=0,"",VLOOKUP($G10,Data!$G$3:$BA$2935,24,FALSE)) | AF10: =IF($H10=0,"",VLOOKUP($G10,Data!$G$3:$BA$2935,25,FALSE)) | AG10: =IF($H10=0,"",VLOOKUP($G10,Data!$G$3:$BA$2935,26,FALSE)) | AH10: =IF($H10=0,"",VLOOKUP($G10,Data!$G$3:$BA$2935,27,FALSE)) | AI10: =IF($H10=0,"",VLOOKUP($G10,Data!$G$3:$BA$2935,28,FALSE)) | AJ10: =IF($H10=0,"",VLOOKUP($G10,Data!$G$3:$BA$2935,29,FALSE)) | AK10: =IF($H10=0,"",VLOOKUP($G10,Data!$G$3:$BA$2935,30,FALSE)) | AL10: =IF($H10=0,"",VLOOKUP($G10,Data!$G$3:$BA$2935,31,FALSE)) | AM10: =IF($H10=0,"",VLOOKUP($G10,Data!$G$3:$BA$2935,32,FALSE)) | AN10: =IF($H10=0,"",VLOOKUP($G10,Data!$G$3:$BA$2935,33,FALSE)) | AO10: =IF($H10=0,"",VLOOKUP($G10,Data!$G$3:$BA$2935,34,FALSE)) | AP10: =IF($H10=0,"",VLOOKUP($G10,Data!$G$3:$BA$2935,35,FALSE)) | AQ10: =IF($H10=0,"",VLOOKUP($G10,Data!$G$3:$BA$2935,36,FALSE)) | AR10: =IF($H10=0,"",VLOOKUP($G10,Data!$G$3:$BA$2935,37,FALSE)) | AS10: =IF($H10=0,"",VLOOKUP($G10,Data!$G$3:$BA$2935,38,FALSE)) | AT10: =IF($H10=0,"",VLOOKUP($G10,Data!$G$3:$BA$2935,39,FALSE))
A11: =PSSE!A20 -> 912021 | B11: =PSSE!B20 -> DOAVIEN_1 | C11: =PSSE!D20 -> 6.3 | D11: =PSSE!E20 -> 55 | E11: =PSSE!F20 -> TD | F11: =PSSE!G20 -> 1 | G11: ="AVR"&C11&D11&E11&F11 -> AVR6.355TD1 | H11: =COUNTIF(Data!$G$3:$BA$2935,AVR!$G11) -> 1 | I11: =IF($H11=0,"",VLOOKUP($G11,Data!$G$3:$BA$2935,2,FALSE)) -> 'ESST4B' | J11: =PSSE!C20 -> 1 | K11: =IF($H11=0,"",VLOOKUP($G11,Data!$G$3:$BA$2935,4,FALSE)) -> 0 | L11: =IF($H11=0,"",VLOOKUP($G11,Data!$G$3:$BA$2935,5,FALSE)) -> 10.75 | M11: =IF($H11=0,"",VLOOKUP($G11,Data!$G$3:$BA$2935,6,FALSE)) -> 10.75 | N11: =IF($H11=0,"",VLOOKUP($G11,Data!$G$3:$BA$2935,7,FALSE)) -> 5 | O11: =IF($H11=0,"",VLOOKUP($G11,Data!$G$3:$BA$2935,8,FALSE)) -> -0.87 | P11: =IF($H11=0,"",VLOOKUP($G11,Data!$G$3:$BA$2935,9,FALSE)) -> 0 | Q11: =IF($H11=0,"",VLOOKUP($G11,Data!$G$3:$BA$2935,10,FALSE)) -> 1 | R11: =IF($H11=0,"",VLOOKUP($G11,Data!$G$3:$BA$2935,11,FALSE)) -> 0 | S11: =IF($H11=0,"",VLOOKUP($G11,Data!$G$3:$BA$2935,12,FALSE)) -> 99 | T11: =IF($H11=0,"",VLOOKUP($G11,Data!$G$3:$BA$2935,13,FALSE)) -> -99 | U11: =IF($H11=0,"",VLOOKUP($G11,Data!$G$3:$BA$2935,14,FALSE)) -> 0 | V11: =IF($H11=0,"",VLOOKUP($G11,Data!$G$3:$BA$2935,15,FALSE)) -> 9.3 | W11: =IF($H11=0,"",VLOOKUP($G11,Data!$G$3:$BA$2935,16,FALSE)) -> 0 | X11: =IF($H11=0,"",VLOOKUP($G11,Data!$G$3:$BA$2935,17,FALSE)) -> 11.63 | Y11: =IF($H11=0,"",VLOOKUP($G11,Data!$G$3:$BA$2935,18,FALSE)) -> 0.113 | Z11: =IF($H11=0,"",VLOOKUP($G11,Data!$G$3:$BA$2935,19,FALSE)) -> 0.124 | AA11: =IF($H11=0,"",VLOOKUP($G11,Data!$G$3:$BA$2935,20,FALSE)) -> 0 | AB11: =IF($H11=0,"",VLOOKUP($G11,Data!$G$3:$BA$2935,21,FALSE)) -> / | AC11: =IF($H11=0,"",VLOOKUP($G11,Data!$G$3:$BA$2935,22,FALSE)) -> / | AD11: =IF($H11=0,"",VLOOKUP($G11,Data!$G$3:$BA$2935,23,FALSE)) | AE11: =IF($H11=0,"",VLOOKUP($G11,Data!$G$3:$BA$2935,24,FALSE)) | AF11: =IF($H11=0,"",VLOOKUP($G11,Data!$G$3:$BA$2935,25,FALSE)) | AG11: =IF($H11=0,"",VLOOKUP($G11,Data!$G$3:$BA$2935,26,FALSE)) | AH11: =IF($H11=0,"",VLOOKUP($G11,Data!$G$3:$BA$2935,27,FALSE)) | AI11: =IF($H11=0,"",VLOOKUP($G11,Data!$G$3:$BA$2935,28,FALSE)) | AJ11: =IF($H11=0,"",VLOOKUP($G11,Data!$G$3:$BA$2935,29,FALSE)) | AK11: =IF($H11=0,"",VLOOKUP($G11,Data!$G$3:$BA$2935,30,FALSE)) | AL11: =IF($H11=0,"",VLOOKUP($G11,Data!$G$3:$BA$2935,31,FALSE)) | AM11: =IF($H11=0,"",VLOOKUP($G11,Data!$G$3:$BA$2935,32,FALSE)) | AN11: =IF($H11=0,"",VLOOKUP($G11,Data!$G$3:$BA$2935,33,FALSE)) | AO11: =IF($H11=0,"",VLOOKUP($G11,Data!$G$3:$BA$2935,34,FALSE)) | AP11: =IF($H11=0,"",VLOOKUP($G11,Data!$G$3:$BA$2935,35,FALSE)) | AQ11: =IF($H11=0,"",VLOOKUP($G11,Data!$G$3:$BA$2935,36,FALSE)) | AR11: =IF($H11=0,"",VLOOKUP($G11,Data!$G$3:$BA$2935,37,FALSE)) | AS11: =IF($H11=0,"",VLOOKUP($G11,Data!$G$3:$BA$2935,38,FALSE)) | AT11: =IF($H11=0,"",VLOOKUP($G11,Data!$G$3:$BA$2935,39,FALSE))
A12: =PSSE!A21 -> 912031 | B12: =PSSE!B21 -> TANVIET_1 | C12: =PSSE!D21 -> 6.3 | D12: =PSSE!E21 -> 55 | E12: =PSSE!F21 -> TD | F12: =PSSE!G21 -> 1 | G12: ="AVR"&C12&D12&E12&F12 -> AVR6.355TD1 | H12: =COUNTIF(Data!$G$3:$BA$2935,AVR!$G12) -> 1 | I12: =IF($H12=0,"",VLOOKUP($G12,Data!$G$3:$BA$2935,2,FALSE)) -> 'ESST4B' | J12: =PSSE!C21 -> 1 | K12: =IF($H12=0,"",VLOOKUP($G12,Data!$G$3:$BA$2935,4,FALSE)) -> 0 | L12: =IF($H12=0,"",VLOOKUP($G12,Data!$G$3:$BA$2935,5,FALSE)) -> 10.75 | M12: =IF($H12=0,"",VLOOKUP($G12,Data!$G$3:$BA$2935,6,FALSE)) -> 10.75 | N12: =IF($H12=0,"",VLOOKUP($G12,Data!$G$3:$BA$2935,7,FALSE)) -> 5 | O12: =IF($H12=0,"",VLOOKUP($G12,Data!$G$3:$BA$2935,8,FALSE)) -> -0.87 | P12: =IF($H12=0,"",VLOOKUP($G12,Data!$G$3:$BA$2935,9,FALSE)) -> 0 | Q12: =IF($H12=0,"",VLOOKUP($G12,Data!$G$3:$BA$2935,10,FALSE)) -> 1 | R12: =IF($H12=0,"",VLOOKUP($G12,Data!$G$3:$BA$2935,11,FALSE)) -> 0 | S12: =IF($H12=0,"",VLOOKUP($G12,Data!$G$3:$BA$2935,12,FALSE)) -> 99 | T12: =IF($H12=0,"",VLOOKUP($G12,Data!$G$3:$BA$2935,13,FALSE)) -> -99 | U12: =IF($H12=0,"",VLOOKUP($G12,Data!$G$3:$BA$2935,14,FALSE)) -> 0 | V12: =IF($H12=0,"",VLOOKUP($G12,Data!$G$3:$BA$2935,15,FALSE)) -> 9.3 | W12: =IF($H12=0,"",VLOOKUP($G12,Data!$G$3:$BA$2935,16,FALSE)) -> 0 | X12: =IF($H12=0,"",VLOOKUP($G12,Data!$G$3:$BA$2935,17,FALSE)) -> 11.63 | Y12: =IF($H12=0,"",VLOOKUP($G12,Data!$G$3:$BA$2935,18,FALSE)) -> 0.113 | Z12: =IF($H12=0,"",VLOOKUP($G12,Data!$G$3:$BA$2935,19,FALSE)) -> 0.124 | AA12: =IF($H12=0,"",VLOOKUP($G12,Data!$G$3:$BA$2935,20,FALSE)) -> 0 | AB12: =IF($H12=0,"",VLOOKUP($G12,Data!$G$3:$BA$2935,21,FALSE)) -> / | AC12: =IF($H12=0,"",VLOOKUP($G12,Data!$G$3:$BA$2935,22,FALSE)) -> / | AD12: =IF($H12=0,"",VLOOKUP($G12,Data!$G$3:$BA$2935,23,FALSE)) | AE12: =IF($H12=0,"",VLOOKUP($G12,Data!$G$3:$BA$2935,24,FALSE)) | AF12: =IF($H12=0,"",VLOOKUP($G12,Data!$G$3:$BA$2935,25,FALSE)) | AG12: =IF($H12=0,"",VLOOKUP($G12,Data!$G$3:$BA$2935,26,FALSE)) | AH12: =IF($H12=0,"",VLOOKUP($G12,Data!$G$3:$BA$2935,27,FALSE)) | AI12: =IF($H12=0,"",VLOOKUP($G12,Data!$G$3:$BA$2935,28,FALSE)) | AJ12: =IF($H12=0,"",VLOOKUP($G12,Data!$G$3:$BA$2935,29,FALSE)) | AK12: =IF($H12=0,"",VLOOKUP($G12,Data!$G$3:$BA$2935,30,FALSE)) | AL12: =IF($H12=0,"",VLOOKUP($G12,Data!$G$3:$BA$2935,31,FALSE)) | AM12: =IF($H12=0,"",VLOOKUP($G12,Data!$G$3:$BA$2935,32,FALSE)) | AN12: =IF($H12=0,"",VLOOKUP($G12,Data!$G$3:$BA$2935,33,FALSE)) | AO12: =IF($H12=0,"",VLOOKUP($G12,Data!$G$3:$BA$2935,34,FALSE)) | AP12: =IF($H12=0,"",VLOOKUP($G12,Data!$G$3:$BA$2935,35,FALSE)) | AQ12: =IF($H12=0,"",VLOOKUP($G12,Data!$G$3:$BA$2935,36,FALSE)) | AR12: =IF($H12=0,"",VLOOKUP($G12,Data!$G$3:$BA$2935,37,FALSE)) | AS12: =IF($H12=0,"",VLOOKUP($G12,Data!$G$3:$BA$2935,38,FALSE)) | AT12: =IF($H12=0,"",VLOOKUP($G12,Data!$G$3:$BA$2935,39,FALSE))
